Workbook

Sheet P
A1: NOME | B1: CAT | C1: MAX | D1: STATO | E1: COSTO_REALE | F1: MAX_D | G1: NOTE
A2: BUTEZ | B2: Pun | C2: 18 | D2: L | F2: =IF(D2<>"L","-",IF(COUNTA(P!E$2:E$1000)+COUNTA(D!E$2:E$1000)+COUNTA('C'!E$2:E$1000)+COUNTA(A!E$2:E$1000)=0,C2,ROUND(C2*MAX(0.1,IFERROR(Dashboard!B$3/Dashboard!B$10,1))*(1+Dashboard!F$5*IF(B2="Occ",0.5,IF(B2="Pun",0.35,IF(B2="Tit",0.25,IF(B2="Scm",0.15,0.05)))))*IF(OR(B2="Occ",B2="Pun"),Dashboard!V$5,IF(B2="Tit",Dashboard!W$5,Dashboard!X$5)),0))) -> 18 | G2: eventualmente da trio
A3: CAPRILE | B3: Pun | C3: 10 | D3: L | F3: =IF(D3<>"L","-",IF(COUNTA(P!E$2:E$1000)+COUNTA(D!E$2:E$1000)+COUNTA('C'!E$2:E$1000)+COUNTA(A!E$2:E$1000)=0,C3,ROUND(C3*MAX(0.1,IFERROR(Dashboard!B$3/Dashboard!B$10,1))*(1+Dashboard!F$5*IF(B3="Occ",0.5,IF(B3="Pun",0.35,IF(B3="Tit",0.25,IF(B3="Scm",0.15,0.05)))))*IF(OR(B3="Occ",B3="Pun"),Dashboard!V$5,IF(B3="Tit",Dashboard!W$5,Dashboard!X$5)),0))) -> 10
A4: CARNESECCHI | B4: Occ | C4: 18 | D4: L | F4: =IF(D4<>"L","-",IF(COUNTA(P!E$2:E$1000)+COUNTA(D!E$2:E$1000)+COUNTA('C'!E$2:E$1000)+COUNTA(A!E$2:E$1000)=0,C4,ROUND(C4*MAX(0.1,IFERROR(Dashboard!B$3/Dashboard!B$10,1))*(1+Dashboard!F$5*IF(B4="Occ",0.5,IF(B4="Pun",0.35,IF(B4="Tit",0.25,IF(B4="Scm",0.15,0.05)))))*IF(OR(B4="Occ",B4="Pun"),Dashboard!V$5,IF(B4="Tit",Dashboard!W$5,Dashboard!X$5)),0))) -> 18 | G4: eventualmente da trio
A5: CORVI | B5: Sca | C5: 1 | D5: L | F5: =IF(D5<>"L","-",IF(COUNTA(P!E$2:E$1000)+COUNTA(D!E$2:E$1000)+COUNTA('C'!E$2:E$1000)+COUNTA(A!E$2:E$1000)=0,C5,ROUND(C5*MAX(0.1,IFERROR(Dashboard!B$3/Dashboard!B$10,1))*(1+Dashboard!F$5*IF(B5="Occ",0.5,IF(B5="Pun",0.35,IF(B5="Tit",0.25,IF(B5="Scm",0.15,0.05)))))*IF(OR(B5="Occ",B5="Pun"),Dashboard!V$5,IF(B5="Tit",Dashboard!W$5,Dashboard!X$5)),0))) -> 1
A6: DE GEA | B6: Occ | C6: 12 | D6: L | F6: =IF(D6<>"L","-",IF(COUNTA(P!E$2:E$1000)+COUNTA(D!E$2:E$1000)+COUNTA('C'!E$2:E$1000)+COUNTA(A!E$2:E$1000)=0,C6,ROUND(C6*MAX(0.1,IFERROR(Dashboard!B$3/Dashboard!B$10,1))*(1+Dashboard!F$5*IF(B6="Occ",0.5,IF(B6="Pun",0.35,IF(B6="Tit",0.25,IF(B6="Scm",0.15,0.05)))))*IF(OR(B6="Occ",B6="Pun"),Dashboard!V$5,IF(B6="Tit",Dashboard!W$5,Dashboard!X$5)),0))) -> 12
A7: FALCONE | B7: Pun | C7: 12 | D7: L | F7: =IF(D7<>"L","-",IF(COUNTA(P!E$2:E$1000)+COUNTA(D!E$2:E$1000)+COUNTA('C'!E$2:E$1000)+COUNTA(A!E$2:E$1000)=0,C7,ROUND(C7*MAX(0.1,IFERROR(Dashboard!B$3/Dashboard!B$10,1))*(1+Dashboard!F$5*IF(B7="Occ",0.5,IF(B7="Pun",0.35,IF(B7="Tit",0.25,IF(B7="Scm",0.15,0.05)))))*IF(OR(B7="Occ",B7="Pun"),Dashboard!V$5,IF(B7="Tit",Dashboard!W$5,Dashboard!X$5)),0))) -> 12
A8: JOSEP MARTINEZ | B8: Occ | C8: 30 | D8: L | F8: =IF(D8<>"L","-",IF(COUNTA(P!E$2:E$1000)+COUNTA(D!E$2:E$1000)+COUNTA('C'!E$2:E$1000)+COUNTA(A!E$2:E$1000)=0,C8,ROUND(C8*MAX(0.1,IFERROR(Dashboard!B$3/Dashboard!B$10,1))*(1+Dashboard!F$5*IF(B8="Occ",0.5,IF(B8="Pun",0.35,IF(B8="Tit",0.25,IF(B8="Scm",0.15,0.05)))))*IF(OR(B8="Occ",B8="Pun"),Dashboard!V$5,IF(B8="Tit",Dashboard!W$5,Dashboard!X$5)),0))) -> 30 | G8: da trio
A9: MAIGNAN | B9: Occ | C9: 25 | D9: L | F9: =IF(D9<>"L","-",IF(COUNTA(P!E$2:E$1000)+COUNTA(D!E$2:E$1000)+COUNTA('C'!E$2:E$1000)+COUNTA(A!E$2:E$1000)=0,C9,ROUND(C9*MAX(0.1,IFERROR(Dashboard!B$3/Dashboard!B$10,1))*(1+Dashboard!F$5*IF(B9="Occ",0.5,IF(B9="Pun",0.35,IF(B9="Tit",0.25,IF(B9="Scm",0.15,0.05)))))*IF(OR(B9="Occ",B9="Pun"),Dashboard!V$5,IF(B9="Tit",Dashboard!W$5,Dashboard!X$5)),0))) -> 25 | G9: da trio
A10: MANDAS | B10: Pun | C10: 14 | D10: L | F10: =IF(D10<>"L","-",IF(COUNTA(P!E$2:E$1000)+COUNTA(D!E$2:E$1000)+COUNTA('C'!E$2:E$1000)+COUNTA(A!E$2:E$1000)=0,C10,ROUND(C10*MAX(0.1,IFERROR(Dashboard!B$3/Dashboard!B$10,1))*(1+Dashboard!F$5*IF(B10="Occ",0.5,IF(B10="Pun",0.35,IF(B10="Tit",0.25,IF(B10="Scm",0.15,0.05)))))*IF(OR(B10="Occ",B10="Pun"),Dashboard!V$5,IF(B10="Tit",Dashboard!W$5,Dashboard!X$5)),0))) -> 14
A11: MASCARDI | B11: Scm | C11: 8 | D11: L | F11: =IF(D11<>"L","-",IF(COUNTA(P!E$2:E$1000)+COUNTA(D!E$2:E$1000)+COUNTA('C'!E$2:E$1000)+COUNTA(A!E$2:E$1000)=0,C11,ROUND(C11*MAX(0.1,IFERROR(Dashboard!B$3/Dashboard!B$10,1))*(1+Dashboard!F$5*IF(B11="Occ",0.5,IF(B11="Pun",0.35,IF(B11="Tit",0.25,IF(B11="Scm",0.15,0.05)))))*IF(OR(B11="Occ",B11="Pun"),Dashboard!V$5,IF(B11="Tit",Dashboard!W$5,Dashboard!X$5)),0))) -> 8
A12: MERET / MILINKOVIC | B12: Occ | C12: 30 | D12: L | F12: =IF(D12<>"L","-",IF(COUNTA(P!E$2:E$1000)+COUNTA(D!E$2:E$1000)+COUNTA('C'!E$2:E$1000)+COUNTA(A!E$2:E$1000)=0,C12,ROUND(C12*MAX(0.1,IFERROR(Dashboard!B$3/Dashboard!B$10,1))*(1+Dashboard!F$5*IF(B12="Occ",0.5,IF(B12="Pun",0.35,IF(B12="Tit",0.25,IF(B12="Scm",0.15,0.05)))))*IF(OR(B12="Occ",B12="Pun"),Dashboard!V$5,IF(B12="Tit",Dashboard!W$5,Dashboard!X$5)),0))) -> 30 | G12: da trio
A13: MURIC | B13: Scm | C13: 8 | D13: L | F13: =IF(D13<>"L","-",IF(COUNTA(P!E$2:E$1000)+COUNTA(D!E$2:E$1000)+COUNTA('C'!E$2:E$1000)+COUNTA(A!E$2:E$1000)=0,C13,ROUND(C13*MAX(0.1,IFERROR(Dashboard!B$3/Dashboard!B$10,1))*(1+Dashboard!F$5*IF(B13="Occ",0.5,IF(B13="Pun",0.35,IF(B13="Tit",0.25,IF(B13="Scm",0.15,0.05)))))*IF(OR(B13="Occ",B13="Pun"),Dashboard!V$5,IF(B13="Tit",Dashboard!W$5,Dashboard!X$5)),0))) -> 8
A14: OKOYE | B14: Pun | C14: 14 | D14: L | F14: =IF(D14<>"L","-",IF(COUNTA(P!E$2:E$1000)+COUNTA(D!E$2:E$1000)+COUNTA('C'!E$2:E$1000)+COUNTA(A!E$2:E$1000)=0,C14,ROUND(C14*MAX(0.1,IFERROR(Dashboard!B$3/Dashboard!B$10,1))*(1+Dashboard!F$5*IF(B14="Occ",0.5,IF(B14="Pun",0.35,IF(B14="Tit",0.25,IF(B14="Scm",0.15,0.05)))))*IF(OR(B14="Occ",B14="Pun"),Dashboard!V$5,IF(B14="Tit",Dashboard!W$5,Dashboard!X$5)),0))) -> 14
A15: PALMISANI | B15: Sca | C15: 1 | D15: L | F15: =IF(D15<>"L","-",IF(COUNTA(P!E$2:E$1000)+COUNTA(D!E$2:E$1000)+COUNTA('C'!E$2:E$1000)+COUNTA(A!E$2:E$1000)=0,C15,ROUND(C15*MAX(0.1,IFERROR(Dashboard!B$3/Dashboard!B$10,1))*(1+Dashboard!F$5*IF(B15="Occ",0.5,IF(B15="Pun",0.35,IF(B15="Tit",0.25,IF(B15="Scm",0.15,0.05)))))*IF(OR(B15="Occ",B15="Pun"),Dashboard!V$5,IF(B15="Tit",Dashboard!W$5,Dashboard!X$5)),0))) -> 1
A16: SKORUPSKI | B16: Pun | C16: 12 | D16: L | F16: =IF(D16<>"L","-",IF(COUNTA(P!E$2:E$1000)+COUNTA(D!E$2:E$1000)+COUNTA('C'!E$2:E$1000)+COUNTA(A!E$2:E$1000)=0,C16,ROUND(C16*MAX(0.1,IFERROR(Dashboard!B$3/Dashboard!B$10,1))*(1+Dashboard!F$5*IF(B16="Occ",0.5,IF(B16="Pun",0.35,IF(B16="Tit",0.25,IF(B16="Scm",0.15,0.05)))))*IF(OR(B16="Occ",B16="Pun"),Dashboard!V$5,IF(B16="Tit",Dashboard!W$5,Dashboard!X$5)),0))) -> 12
A17: STANKOVIC | B17: Sca | C17: 1 | D17: L | F17: =IF(D17<>"L","-",IF(COUNTA(P!E$2:E$1000)+COUNTA(D!E$2:E$1000)+COUNTA('C'!E$2:E$1000)+COUNTA(A!E$2:E$1000)=0,C17,ROUND(C17*MAX(0.1,IFERROR(Dashboard!B$3/Dashboard!B$10,1))*(1+Dashboard!F$5*IF(B17="Occ",0.5,IF(B17="Pun",0.35,IF(B17="Tit",0.25,IF(B17="Scm",0.15,0.05)))))*IF(OR(B17="Occ",B17="Pun"),Dashboard!V$5,IF(B17="Tit",Dashboard!W$5,Dashboard!X$5)),0))) -> 1
A18: SVILAR | B18: Occ | C18: 30 | D18: L | F18: =IF(D18<>"L","-",IF(COUNTA(P!E$2:E$1000)+COUNTA(D!E$2:E$1000)+COUNTA('C'!E$2:E$1000)+COUNTA(A!E$2:E$1000)=0,C18,ROUND(C18*MAX(0.1,IFERROR(Dashboard!B$3/Dashboard!B$10,1))*(1+Dashboard!F$5*IF(B18="Occ",0.5,IF(B18="Pun",0.35,IF(B18="Tit",0.25,IF(B18="Scm",0.15,0.05)))))*IF(OR(B18="Occ",B18="Pun"),Dashboard!V$5,IF(B18="Tit",Dashboard!W$5,Dashboard!X$5)),0))) -> 30 | G18: da trio
A19: THIAM | B19: Sca | C19: 1 | D19: L | F19: =IF(D19<>"L","-",IF(COUNTA(P!E$2:E$1000)+COUNTA(D!E$2:E$1000)+COUNTA('C'!E$2:E$1000)+COUNTA(A!E$2:E$1000)=0,C19,ROUND(C19*MAX(0.1,IFERROR(Dashboard!B$3/Dashboard!B$10,1))*(1+Dashboard!F$5*IF(B19="Occ",0.5,IF(B19="Pun",0.35,IF(B19="Tit",0.25,IF(B19="Scm",0.15,0.05)))))*IF(OR(B19="Occ",B19="Pun"),Dashboard!V$5,IF(B19="Tit",Dashboard!W$5,Dashboard!X$5)),0))) -> 1
A20: TURATI | B20: Sca | C20: 1 | D20: L | F20: =IF(D20<>"L","-",IF(COUNTA(P!E$2:E$1000)+COUNTA(D!E$2:E$1000)+COUNTA('C'!E$2:E$1000)+COUNTA(A!E$2:E$1000)=0,C20,ROUND(C20*MAX(0.1,IFERROR(Dashboard!B$3/Dashboard!B$10,1))*(1+Dashboard!F$5*IF(B20="Occ",0.5,IF(B20="Pun",0.35,IF(B20="Tit",0.25,IF(B20="Scm",0.15,0.05)))))*IF(OR(B20="Occ",B20="Pun"),Dashboard!V$5,IF(B20="Tit",Dashboard!W$5,Dashboard!X$5)),0))) -> 1 | G20: riserva di Muric
A21: VICARIO | B21: Occ | C21: 25 | D21: L | F21: =IF(D21<>"L","-",IF(COUNTA(P!E$2:E$1000)+COUNTA(D!E$2:E$1000)+COUNTA('C'!E$2:E$1000)+COUNTA(A!E$2:E$1000)=0,C21,ROUND(C21*MAX(0.1,IFERROR(Dashboard!B$3/Dashboard!B$10,1))*(1+Dashboard!F$5*IF(B21="Occ",0.5,IF(B21="Pun",0.35,IF(B21="Tit",0.25,IF(B21="Scm",0.15,0.05)))))*IF(OR(B21="Occ",B21="Pun"),Dashboard!V$5,IF(B21="Tit",Dashboard!W$5,Dashboard!X$5)),0))) -> 25 | G21: da trio

Sheet D
A1: NOME | B1: CAT | C1: MAX | D1: STATO | E1: COSTO_REALE | F1: MAX_D | G1: NOTE
A2: ABANKWAH | B2: Sca | C2: 1 | D2: L | F2: =IF(D2<>"L","-",IF(COUNTA(P!E$2:E$1000)+COUNTA(D!E$2:E$1000)+COUNTA('C'!E$2:E$1000)+COUNTA(A!E$2:E$1000)=0,C2,ROUND(C2*MAX(0.1,IFERROR(Dashboard!B$3/Dashboard!B$10,1))*(1+Dashboard!F$6*IF(B2="Occ",0.5,IF(B2="Pun",0.35,IF(B2="Tit",0.25,IF(B2="Scm",0.15,0.05)))))*IF(OR(B2="Occ",B2="Pun"),Dashboard!V$6,IF(B2="Tit",Dashboard!W$6,Dashboard!X$6)),0))) -> 1
A3: BADIASHILE | B3: Sca | C3: 1 | D3: L | F3: =IF(D3<>"L","-",IF(COUNTA(P!E$2:E$1000)+COUNTA(D!E$2:E$1000)+COUNTA('C'!E$2:E$1000)+COUNTA(A!E$2:E$1000)=0,C3,ROUND(C3*MAX(0.1,IFERROR(Dashboard!B$3/Dashboard!B$10,1))*(1+Dashboard!F$6*IF(B3="Occ",0.5,IF(B3="Pun",0.35,IF(B3="Tit",0.25,IF(B3="Scm",0.15,0.05)))))*IF(OR(B3="Occ",B3="Pun"),Dashboard!V$6,IF(B3="Tit",Dashboard!W$6,Dashboard!X$6)),0))) -> 1
A4: BARTESAGHI | B4: Pun | C4: 9 | D4: L | F4: =IF(D4<>"L","-",IF(COUNTA(P!E$2:E$1000)+COUNTA(D!E$2:E$1000)+COUNTA('C'!E$2:E$1000)+COUNTA(A!E$2:E$1000)=0,C4,ROUND(C4*MAX(0.1,IFERROR(Dashboard!B$3/Dashboard!B$10,1))*(1+Dashboard!F$6*IF(B4="Occ",0.5,IF(B4="Pun",0.35,IF(B4="Tit",0.25,IF(B4="Scm",0.15,0.05)))))*IF(OR(B4="Occ",B4="Pun"),Dashboard!V$6,IF(B4="Tit",Dashboard!W$6,Dashboard!X$6)),0))) -> 9 | G4: con Estupinan
A5: BASTONI | B5: Occ | C5: 8 | D5: L | F5: =IF(D5<>"L","-",IF(COUNTA(P!E$2:E$1000)+COUNTA(D!E$2:E$1000)+COUNTA('C'!E$2:E$1000)+COUNTA(A!E$2:E$1000)=0,C5,ROUND(C5*MAX(0.1,IFERROR(Dashboard!B$3/Dashboard!B$10,1))*(1+Dashboard!F$6*IF(B5="Occ",0.5,IF(B5="Pun",0.35,IF(B5="Tit",0.25,IF(B5="Scm",0.15,0.05)))))*IF(OR(B5="Occ",B5="Pun"),Dashboard!V$6,IF(B5="Tit",Dashboard!W$6,Dashboard!X$6)),0))) -> 8
A6: BELLA-KOTCHAP | B6: Tit | C6: 1 | D6: L | F6: =IF(D6<>"L","-",IF(COUNTA(P!E$2:E$1000)+COUNTA(D!E$2:E$1000)+COUNTA('C'!E$2:E$1000)+COUNTA(A!E$2:E$1000)=0,C6,ROUND(C6*MAX(0.1,IFERROR(Dashboard!B$3/Dashboard!B$10,1))*(1+Dashboard!F$6*IF(B6="Occ",0.5,IF(B6="Pun",0.35,IF(B6="Tit",0.25,IF(B6="Scm",0.15,0.05)))))*IF(OR(B6="Occ",B6="Pun"),Dashboard!V$6,IF(B6="Tit",Dashboard!W$6,Dashboard!X$6)),0))) -> 1
A7: BELLANOVA | B7: Tit | C7: 6 | D7: L | F7: =IF(D7<>"L","-",IF(COUNTA(P!E$2:E$1000)+COUNTA(D!E$2:E$1000)+COUNTA('C'!E$2:E$1000)+COUNTA(A!E$2:E$1000)=0,C7,ROUND(C7*MAX(0.1,IFERROR(Dashboard!B$3/Dashboard!B$10,1))*(1+Dashboard!F$6*IF(B7="Occ",0.5,IF(B7="Pun",0.35,IF(B7="Tit",0.25,IF(B7="Scm",0.15,0.05)))))*IF(OR(B7="Occ",B7="Pun"),Dashboard!V$6,IF(B7="Tit",Dashboard!W$6,Dashboard!X$6)),0))) -> 6 | G7: con Zappacosta
A8: BERNASCONI | B8: Tit | C8: 6 | D8: L | F8: =IF(D8<>"L","-",IF(COUNTA(P!E$2:E$1000)+COUNTA(D!E$2:E$1000)+COUNTA('C'!E$2:E$1000)+COUNTA(A!E$2:E$1000)=0,C8,ROUND(C8*MAX(0.1,IFERROR(Dashboard!B$3/Dashboard!B$10,1))*(1+Dashboard!F$6*IF(B8="Occ",0.5,IF(B8="Pun",0.35,IF(B8="Tit",0.25,IF(B8="Scm",0.15,0.05)))))*IF(OR(B8="Occ",B8="Pun"),Dashboard!V$6,IF(B8="Tit",Dashboard!W$6,Dashboard!X$6)),0))) -> 6
A9: BIRINDELLI | B9: Pun | C9: 6 | D9: L | F9: =IF(D9<>"L","-",IF(COUNTA(P!E$2:E$1000)+COUNTA(D!E$2:E$1000)+COUNTA('C'!E$2:E$1000)+COUNTA(A!E$2:E$1000)=0,C9,ROUND(C9*MAX(0.1,IFERROR(Dashboard!B$3/Dashboard!B$10,1))*(1+Dashboard!F$6*IF(B9="Occ",0.5,IF(B9="Pun",0.35,IF(B9="Tit",0.25,IF(B9="Scm",0.15,0.05)))))*IF(OR(B9="Occ",B9="Pun"),Dashboard!V$6,IF(B9="Tit",Dashboard!W$6,Dashboard!X$6)),0))) -> 6
A10: BISSECK | B10: Occ | C10: 8 | D10: L | F10: =IF(D10<>"L","-",IF(COUNTA(P!E$2:E$1000)+COUNTA(D!E$2:E$1000)+COUNTA('C'!E$2:E$1000)+COUNTA(A!E$2:E$1000)=0,C10,ROUND(C10*MAX(0.1,IFERROR(Dashboard!B$3/Dashboard!B$10,1))*(1+Dashboard!F$6*IF(B10="Occ",0.5,IF(B10="Pun",0.35,IF(B10="Tit",0.25,IF(B10="Scm",0.15,0.05)))))*IF(OR(B10="Occ",B10="Pun"),Dashboard!V$6,IF(B10="Tit",Dashboard!W$6,Dashboard!X$6)),0))) -> 8
A11: BRACAGLIA | B11: Sca | C11: 1 | D11: L | F11: =IF(D11<>"L","-",IF(COUNTA(P!E$2:E$1000)+COUNTA(D!E$2:E$1000)+COUNTA('C'!E$2:E$1000)+COUNTA(A!E$2:E$1000)=0,C11,ROUND(C11*MAX(0.1,IFERROR(Dashboard!B$3/Dashboard!B$10,1))*(1+Dashboard!F$6*IF(B11="Occ",0.5,IF(B11="Pun",0.35,IF(B11="Tit",0.25,IF(B11="Scm",0.15,0.05)))))*IF(OR(B11="Occ",B11="Pun"),Dashboard!V$6,IF(B11="Tit",Dashboard!W$6,Dashboard!X$6)),0))) -> 1
A12: BREMER | B12: Occ | C12: 8 | D12: L | F12: =IF(D12<>"L","-",IF(COUNTA(P!E$2:E$1000)+COUNTA(D!E$2:E$1000)+COUNTA('C'!E$2:E$1000)+COUNTA(A!E$2:E$1000)=0,C12,ROUND(C12*MAX(0.1,IFERROR(Dashboard!B$3/Dashboard!B$10,1))*(1+Dashboard!F$6*IF(B12="Occ",0.5,IF(B12="Pun",0.35,IF(B12="Tit",0.25,IF(B12="Scm",0.15,0.05)))))*IF(OR(B12="Occ",B12="Pun"),Dashboard!V$6,IF(B12="Tit",Dashboard!W$6,Dashboard!X$6)),0))) -> 8
A13: BUONGIORNO | B13: Tit | C13: 3 | D13: L | F13: =IF(D13<>"L","-",IF(COUNTA(P!E$2:E$1000)+COUNTA(D!E$2:E$1000)+COUNTA('C'!E$2:E$1000)+COUNTA(A!E$2:E$1000)=0,C13,ROUND(C13*MAX(0.1,IFERROR(Dashboard!B$3/Dashboard!B$10,1))*(1+Dashboard!F$6*IF(B13="Occ",0.5,IF(B13="Pun",0.35,IF(B13="Tit",0.25,IF(B13="Scm",0.15,0.05)))))*IF(OR(B13="Occ",B13="Pun"),Dashboard!V$6,IF(B13="Tit",Dashboard!W$6,Dashboard!X$6)),0))) -> 3
A14: CALVANI | B14: Tit | C14: 1 | D14: L | F14: =IF(D14<>"L","-",IF(COUNTA(P!E$2:E$1000)+COUNTA(D!E$2:E$1000)+COUNTA('C'!E$2:E$1000)+COUNTA(A!E$2:E$1000)=0,C14,ROUND(C14*MAX(0.1,IFERROR(Dashboard!B$3/Dashboard!B$10,1))*(1+Dashboard!F$6*IF(B14="Occ",0.5,IF(B14="Pun",0.35,IF(B14="Tit",0.25,IF(B14="Scm",0.15,0.05)))))*IF(OR(B14="Occ",B14="Pun"),Dashboard!V$6,IF(B14="Tit",Dashboard!W$6,Dashboard!X$6)),0))) -> 1
A15: CAMBIASO | B15: Occ | C15: 8 | D15: L | F15: =IF(D15<>"L","-",IF(COUNTA(P!E$2:E$1000)+COUNTA(D!E$2:E$1000)+COUNTA('C'!E$2:E$1000)+COUNTA(A!E$2:E$1000)=0,C15,ROUND(C15*MAX(0.1,IFERROR(Dashboard!B$3/Dashboard!B$10,1))*(1+Dashboard!F$6*IF(B15="Occ",0.5,IF(B15="Pun",0.35,IF(B15="Tit",0.25,IF(B15="Scm",0.15,0.05)))))*IF(OR(B15="Occ",B15="Pun"),Dashboard!V$6,IF(B15="Tit",Dashboard!W$6,Dashboard!X$6)),0))) -> 8
A16: CARBONI A. | B16: Tit | C16: 1 | D16: L | F16: =IF(D16<>"L","-",IF(COUNTA(P!E$2:E$1000)+COUNTA(D!E$2:E$1000)+COUNTA('C'!E$2:E$1000)+COUNTA(A!E$2:E$1000)=0,C16,ROUND(C16*MAX(0.1,IFERROR(Dashboard!B$3/Dashboard!B$10,1))*(1+Dashboard!F$6*IF(B16="Occ",0.5,IF(B16="Pun",0.35,IF(B16="Tit",0.25,IF(B16="Scm",0.15,0.05)))))*IF(OR(B16="Occ",B16="Pun"),Dashboard!V$6,IF(B16="Tit",Dashboard!W$6,Dashboard!X$6)),0))) -> 1
A17: CELIK | B17: Sca | C17: 1 | D17: L | F17: =IF(D17<>"L","-",IF(COUNTA(P!E$2:E$1000)+COUNTA(D!E$2:E$1000)+COUNTA('C'!E$2:E$1000)+COUNTA(A!E$2:E$1000)=0,C17,ROUND(C17*MAX(0.1,IFERROR(Dashboard!B$3/Dashboard!B$10,1))*(1+Dashboard!F$6*IF(B17="Occ",0.5,IF(B17="Pun",0.35,IF(B17="Tit",0.25,IF(B17="Scm",0.15,0.05)))))*IF(OR(B17="Occ",B17="Pun"),Dashboard!V$6,IF(B17="Tit",Dashboard!W$6,Dashboard!X$6)),0))) -> 1
A18: CHALOBAH | B18: Scm | C18: 1 | D18: L | F18: =IF(D18<>"L","-",IF(COUNTA(P!E$2:E$1000)+COUNTA(D!E$2:E$1000)+COUNTA('C'!E$2:E$1000)+COUNTA(A!E$2:E$1000)=0,C18,ROUND(C18*MAX(0.1,IFERROR(Dashboard!B$3/Dashboard!B$10,1))*(1+Dashboard!F$6*IF(B18="Occ",0.5,IF(B18="Pun",0.35,IF(B18="Tit",0.25,IF(B18="Scm",0.15,0.05)))))*IF(OR(B18="Occ",B18="Pun"),Dashboard!V$6,IF(B18="Tit",Dashboard!W$6,Dashboard!X$6)),0))) -> 1
A19: CITTADINI | B19: Scm | C19: 1 | D19: L | F19: =IF(D19<>"L","-",IF(COUNTA(P!E$2:E$1000)+COUNTA(D!E$2:E$1000)+COUNTA('C'!E$2:E$1000)+COUNTA(A!E$2:E$1000)=0,C19,ROUND(C19*MAX(0.1,IFERROR(Dashboard!B$3/Dashboard!B$10,1))*(1+Dashboard!F$6*IF(B19="Occ",0.5,IF(B19="Pun",0.35,IF(B19="Tit",0.25,IF(B19="Scm",0.15,0.05)))))*IF(OR(B19="Occ",B19="Pun"),Dashboard!V$6,IF(B19="Tit",Dashboard!W$6,Dashboard!X$6)),0))) -> 1
... A26: DI LORENZO | B26: Occ | C26: 6 | D26: L | F26: =IF(D26<>"L","-",IF(COUNTA(P!E$2:E$1000)+COUNTA(D!E$2:E$1000)+COUNTA('C'!E$2:E$1000)+COUNTA(A!E$2:E$1000)=0,C26,ROUND(C26*MAX(0.1,IFERROR(Dashboard!B$3/Dashboard!B$10,1))*(1+Dashboard!F$6*IF(B26="Occ",0.5,IF(B26="Pun",0.35,IF(B26="Tit",0.25,IF(B26="Scm",0.15,0.05)))))*IF(OR(B26="Occ",B26="Pun"),Dashboard!V$6,IF(B26="Tit",Dashboard!W$6,Dashboard!X$6)),0))) -> 6
A27: DIMARCO | B27: Occ | C27: 17 | D27: L | F27: =IF(D27<>"L","-",IF(COUNTA(P!E$2:E$1000)+COUNTA(D!E$2:E$1000)+COUNTA('C'!E$2:E$1000)+COUNTA(A!E$2:E$1000)=0,C27,ROUND(C27*MAX(0.1,IFERROR(Dashboard!B$3/Dashboard!B$10,1))*(1+Dashboard!F$6*IF(B27="Occ",0.5,IF(B27="Pun",0.35,IF(B27="Tit",0.25,IF(B27="Scm",0.15,0.05)))))*IF(OR(B27="Occ",B27="Pun"),Dashboard!V$6,IF(B27="Tit",Dashboard!W$6,Dashboard!X$6)),0))) -> 17 | G27: Piaz.
A28: DODO' | B28: Tit | C28: 7 | D28: L | F28: =IF(D28<>"L","-",IF(COUNTA(P!E$2:E$1000)+COUNTA(D!E$2:E$1000)+COUNTA('C'!E$2:E$1000)+COUNTA(A!E$2:E$1000)=0,C28,ROUND(C28*MAX(0.1,IFERROR(Dashboard!B$3/Dashboard!B$10,1))*(1+Dashboard!F$6*IF(B28="Occ",0.5,IF(B28="Pun",0.35,IF(B28="Tit",0.25,IF(B28="Scm",0.15,0.05)))))*IF(OR(B28="Occ",B28="Pun"),Dashboard!V$6,IF(B28="Tit",Dashboard!W$6,Dashboard!X$6)),0))) -> 7
A29: DOEKHI | B29: Sca | C29: 1 | D29: L | F29: =IF(D29<>"L","-",IF(COUNTA(P!E$2:E$1000)+COUNTA(D!E$2:E$1000)+COUNTA('C'!E$2:E$1000)+COUNTA(A!E$2:E$1000)=0,C29,ROUND(C29*MAX(0.1,IFERROR(Dashboard!B$3/Dashboard!B$10,1))*(1+Dashboard!F$6*IF(B29="Occ",0.5,IF(B29="Pun",0.35,IF(B29="Tit",0.25,IF(B29="Scm",0.15,0.05)))))*IF(OR(B29="Occ",B29="Pun"),Dashboard!V$6,IF(B29="Tit",Dashboard!W$6,Dashboard!X$6)),0))) -> 1
A30: DOIG | B30: Scm | C30: 1 | D30: L | F30: =IF(D30<>"L","-",IF(COUNTA(P!E$2:E$1000)+COUNTA(D!E$2:E$1000)+COUNTA('C'!E$2:E$1000)+COUNTA(A!E$2:E$1000)=0,C30,ROUND(C30*MAX(0.1,IFERROR(Dashboard!B$3/Dashboard!B$10,1))*(1+Dashboard!F$6*IF(B30="Occ",0.5,IF(B30="Pun",0.35,IF(B30="Tit",0.25,IF(B30="Scm",0.15,0.05)))))*IF(OR(B30="Occ",B30="Pun"),Dashboard!V$6,IF(B30="Tit",Dashboard!W$6,Dashboard!X$6)),0))) -> 1 | G30: con Obrador
A31: DRAGUSIN | B31: Tit | C31: 1 | D31: L | F31: =IF(D31<>"L","-",IF(COUNTA(P!E$2:E$1000)+COUNTA(D!E$2:E$1000)+COUNTA('C'!E$2:E$1000)+COUNTA(A!E$2:E$1000)=0,C31,ROUND(C31*MAX(0.1,IFERROR(Dashboard!B$3/Dashboard!B$10,1))*(1+Dashboard!F$6*IF(B31="Occ",0.5,IF(B31="Pun",0.35,IF(B31="Tit",0.25,IF(B31="Scm",0.15,0.05)))))*IF(OR(B31="Occ",B31="Pun"),Dashboard!V$6,IF(B31="Tit",Dashboard!W$6,Dashboard!X$6)),0))) -> 1
A32: ESTUPINAN | B32: Occ | C32: 4 | D32: L | F32: =IF(D32<>"L","-",IF(COUNTA(P!E$2:E$1000)+COUNTA(D!E$2:E$1000)+COUNTA('C'!E$2:E$1000)+COUNTA(A!E$2:E$1000)=0,C32,ROUND(C32*MAX(0.1,IFERROR(Dashboard!B$3/Dashboard!B$10,1))*(1+Dashboard!F$6*IF(B32="Occ",0.5,IF(B32="Pun",0.35,IF(B32="Tit",0.25,IF(B32="Scm",0.15,0.05)))))*IF(OR(B32="Occ",B32="Pun"),Dashboard!V$6,IF(B32="Tit",Dashboard!W$6,Dashboard!X$6)),0))) -> 4 | G32: con Bartesaghi
A33: FLORIANI M. | B33: Sca | C33: 1 | D33: L | F33: =IF(D33<>"L","-",IF(COUNTA(P!E$2:E$1000)+COUNTA(D!E$2:E$1000)+COUNTA('C'!E$2:E$1000)+COUNTA(A!E$2:E$1000)=0,C33,ROUND(C33*MAX(0.1,IFERROR(Dashboard!B$3/Dashboard!B$10,1))*(1+Dashboard!F$6*IF(B33="Occ",0.5,IF(B33="Pun",0.35,IF(B33="Tit",0.25,IF(B33="Scm",0.15,0.05)))))*IF(OR(B33="Occ",B33="Pun"),Dashboard!V$6,IF(B33="Tit",Dashboard!W$6,Dashboard!X$6)),0))) -> 1
A34: FORTINI | B34: Scm | C34: 1 | D34: L | F34: =IF(D34<>"L","-",IF(COUNTA(P!E$2:E$1000)+COUNTA(D!E$2:E$1000)+COUNTA('C'!E$2:E$1000)+COUNTA(A!E$2:E$1000)=0,C34,ROUND(C34*MAX(0.1,IFERROR(Dashboard!B$3/Dashboard!B$10,1))*(1+Dashboard!F$6*IF(B34="Occ",0.5,IF(B34="Pun",0.35,IF(B34="Tit",0.25,IF(B34="Scm",0.15,0.05)))))*IF(OR(B34="Occ",B34="Pun"),Dashboard!V$6,IF(B34="Tit",Dashboard!W$6,Dashboard!X$6)),0))) -> 1 | G34: con Pedersen
A35: FRANJIC | B35: Sca | C35: 1 | D35: L | F35: =IF(D35<>"L","-",IF(COUNTA(P!E$2:E$1000)+COUNTA(D!E$2:E$1000)+COUNTA('C'!E$2:E$1000)+COUNTA(A!E$2:E$1000)=0,C35,ROUND(C35*MAX(0.1,IFERROR(Dashboard!B$3/Dashboard!B$10,1))*(1+Dashboard!F$6*IF(B35="Occ",0.5,IF(B35="Pun",0.35,IF(B35="Tit",0.25,IF(B35="Scm",0.15,0.05)))))*IF(OR(B35="Occ",B35="Pun"),Dashboard!V$6,IF(B35="Tit",Dashboard!W$6,Dashboard!X$6)),0))) -> 1
A36: GABBIA | B36: Tit | C36: 3 | D36: L | F36: =IF(D36<>"L","-",IF(COUNTA(P!E$2:E$1000)+COUNTA(D!E$2:E$1000)+COUNTA('C'!E$2:E$1000)+COUNTA(A!E$2:E$1000)=0,C36,ROUND(C36*MAX(0.1,IFERROR(Dashboard!B$3/Dashboard!B$10,1))*(1+Dashboard!F$6*IF(B36="Occ",0.5,IF(B36="Pun",0.35,IF(B36="Tit",0.25,IF(B36="Scm",0.15,0.05)))))*IF(OR(B36="Occ",B36="Pun"),Dashboard!V$6,IF(B36="Tit",Dashboard!W$6,Dashboard!X$6)),0))) -> 3
A37: GALLO | B37: Tit | C37: 3 | D37: L | F37: =IF(D37<>"L","-",IF(COUNTA(P!E$2:E$1000)+COUNTA(D!E$2:E$1000)+COUNTA('C'!E$2:E$1000)+COUNTA(A!E$2:E$1000)=0,C37,ROUND(C37*MAX(0.1,IFERROR(Dashboard!B$3/Dashboard!B$10,1))*(1+Dashboard!F$6*IF(B37="Occ",0.5,IF(B37="Pun",0.35,IF(B37="Tit",0.25,IF(B37="Scm",0.15,0.05)))))*IF(OR(B37="Occ",B37="Pun"),Dashboard!V$6,IF(B37="Tit",Dashboard!W$6,Dashboard!X$6)),0))) -> 3
A38: GASPAR | B38: Tit | C38: 1 | D38: L | F38: =IF(D38<>"L","-",IF(COUNTA(P!E$2:E$1000)+COUNTA(D!E$2:E$1000)+COUNTA('C'!E$2:E$1000)+COUNTA(A!E$2:E$1000)=0,C38,ROUND(C38*MAX(0.1,IFERROR(Dashboard!B$3/Dashboard!B$10,1))*(1+Dashboard!F$6*IF(B38="Occ",0.5,IF(B38="Pun",0.35,IF(B38="Tit",0.25,IF(B38="Scm",0.15,0.05)))))*IF(OR(B38="Occ",B38="Pun"),Dashboard!V$6,IF(B38="Tit",Dashboard!W$6,Dashboard!X$6)),0))) -> 1
A39: GILA | B39: Occ | C39: 4 | D39: L | F39: =IF(D39<>"L","-",IF(COUNTA(P!E$2:E$1000)+COUNTA(D!E$2:E$1000)+COUNTA('C'!E$2:E$1000)+COUNTA(A!E$2:E$1000)=0,C39,ROUND(C39*MAX(0.1,IFERROR(Dashboard!B$3/Dashboard!B$10,1))*(1+Dashboard!F$6*IF(B39="Occ",0.5,IF(B39="Pun",0.35,IF(B39="Tit",0.25,IF(B39="Scm",0.15,0.05)))))*IF(OR(B39="Occ",B39="Pun"),Dashboard!V$6,IF(B39="Tit",Dashboard!W$6,Dashboard!X$6)),0))) -> 4
A40: HAINAUT | B40: Scm | C40: 1 | D40: L | F40: =IF(D40<>"L","-",IF(COUNTA(P!E$2:E$1000)+COUNTA(D!E$2:E$1000)+COUNTA('C'!E$2:E$1000)+COUNTA(A!E$2:E$1000)=0,C40,ROUND(C40*MAX(0.1,IFERROR(Dashboard!B$3/Dashboard!B$10,1))*(1+Dashboard!F$6*IF(B40="Occ",0.5,IF(B40="Pun",0.35,IF(B40="Tit",0.25,IF(B40="Scm",0.15,0.05)))))*IF(OR(B40="Occ",B40="Pun"),Dashboard!V$6,IF(B40="Tit",Dashboard!W$6,Dashboard!X$6)),0))) -> 1
A41: HAPS | B41: Sca | C41: 1 | D41: L | F41: =IF(D41<>"L","-",IF(COUNTA(P!E$2:E$1000)+COUNTA(D!E$2:E$1000)+COUNTA('C'!E$2:E$1000)+COUNTA(A!E$2:E$1000)=0,C41,ROUND(C41*MAX(0.1,IFERROR(Dashboard!B$3/Dashboard!B$10,1))*(1+Dashboard!F$6*IF(B41="Occ",0.5,IF(B41="Pun",0.35,IF(B41="Tit",0.25,IF(B41="Scm",0.15,0.05)))))*IF(OR(B41="Occ",B41="Pun"),Dashboard!V$6,IF(B41="Tit",Dashboard!W$6,Dashboard!X$6)),0))) -> 1
A42: HEGGEM | B42: Tit | C42: 1 | D42: L | F42: =IF(D42<>"L","-",IF(COUNTA(P!E$2:E$1000)+COUNTA(D!E$2:E$1000)+COUNTA('C'!E$2:E$1000)+COUNTA(A!E$2:E$1000)=0,C42,ROUND(C42*MAX(0.1,IFERROR(Dashboard!B$3/Dashboard!B$10,1))*(1+Dashboard!F$6*IF(B42="Occ",0.5,IF(B42="Pun",0.35,IF(B42="Tit",0.25,IF(B42="Scm",0.15,0.05)))))*IF(OR(B42="Occ",B42="Pun"),Dashboard!V$6,IF(B42="Tit",Dashboard!W$6,Dashboard!X$6)),0))) -> 1
A43: HELLAND | B43: Sca | C43: 1 | D43: L | F43: =IF(D43<>"L","-",IF(COUNTA(P!E$2:E$1000)+COUNTA(D!E$2:E$1000)+COUNTA('C'!E$2:E$1000)+COUNTA(A!E$2:E$1000)=0,C43,ROUND(C43*MAX(0.1,IFERROR(Dashboard!B$3/Dashboard!B$10,1))*(1+Dashboard!F$6*IF(B43="Occ",0.5,IF(B43="Pun",0.35,IF(B43="Tit",0.25,IF(B43="Scm",0.15,0.05)))))*IF(OR(B43="Occ",B43="Pun"),Dashboard!V$6,IF(B43="Tit",Dashboard!W$6,Dashboard!X$6)),0))) -> 1
A44: HERMOSO | B44: Pun | C44: 10 | D44: L | F44: =IF(D44<>"L","-",IF(COUNTA(P!E$2:E$1000)+COUNTA(D!E$2:E$1000)+COUNTA('C'!E$2:E$1000)+COUNTA(A!E$2:E$1000)=0,C44,ROUND(C44*MAX(0.1,IFERROR(Dashboard!B$3/Dashboard!B$10,1))*(1+Dashboard!F$6*IF(B44="Occ",0.5,IF(B44="Pun",0.35,IF(B44="Tit",0.25,IF(B44="Scm",0.15,0.05)))))*IF(OR(B44="Occ",B44="Pun"),Dashboard!V$6,IF(B44="Tit",Dashboard!W$6,Dashboard!X$6)),0))) -> 10
A45: HIEN | B45: Sca | C45: 1 | D45: L | F45: =IF(D45<>"L","-",IF(COUNTA(P!E$2:E$1000)+COUNTA(D!E$2:E$1000)+COUNTA('C'!E$2:E$1000)+COUNTA(A!E$2:E$1000)=0,C45,ROUND(C45*MAX(0.1,IFERROR(Dashboard!B$3/Dashboard!B$10,1))*(1+Dashboard!F$6*IF(B45="Occ",0.5,IF(B45="Pun",0.35,IF(B45="Tit",0.25,IF(B45="Scm",0.15,0.05)))))*IF(OR(B45="Occ",B45="Pun"),Dashboard!V$6,IF(B45="Tit",Dashboard!W$6,Dashboard!X$6)),0))) -> 1
A46: IDZES | B46: Tit | C46: 1 | D46: L | F46: =IF(D46<>"L","-",IF(COUNTA(P!E$2:E$1000)+COUNTA(D!E$2:E$1000)+COUNTA('C'!E$2:E$1000)+COUNTA(A!E$2:E$1000)=0,C46,ROUND(C46*MAX(0.1,IFERROR(Dashboard!B$3/Dashboard!B$10,1))*(1+Dashboard!F$6*IF(B46="Occ",0.5,IF(B46="Pun",0.35,IF(B46="Tit",0.25,IF(B46="Scm",0.15,0.05)))))*IF(OR(B46="Occ",B46="Pun"),Dashboard!V$6,IF(B46="Tit",Dashboard!W$6,Dashboard!X$6)),0))) -> 1
...

Sheet C
A1: NOME | B1: CAT | C1: MAX | D1: STATO | E1: COSTO_REALE | F1: MAX_D | G1: NOTE
A2: ADOPO | B2: Tit | C2: 1 | D2: L | F2: =IF(D2<>"L","-",IF(COUNTA(P!E$2:E$1000)+COUNTA(D!E$2:E$1000)+COUNTA('C'!E$2:E$1000)+COUNTA(A!E$2:E$1000)=0,C2,ROUND(C2*MAX(0.1,IFERROR(Dashboard!B$3/Dashboard!B$10,1))*(1+Dashboard!F$7*IF(B2="Occ",0.5,IF(B2="Pun",0.35,IF(B2="Tit",0.25,IF(B2="Scm",0.15,0.05)))))*IF(OR(B2="Occ",B2="Pun"),Dashboard!V$7,IF(B2="Tit",Dashboard!W$7,Dashboard!X$7)),0))) -> 1
A3: ADZIC | B3: Pun | C3: 3 | D3: L | F3: =IF(D3<>"L","-",IF(COUNTA(P!E$2:E$1000)+COUNTA(D!E$2:E$1000)+COUNTA('C'!E$2:E$1000)+COUNTA(A!E$2:E$1000)=0,C3,ROUND(C3*MAX(0.1,IFERROR(Dashboard!B$3/Dashboard!B$10,1))*(1+Dashboard!F$7*IF(B3="Occ",0.5,IF(B3="Pun",0.35,IF(B3="Tit",0.25,IF(B3="Scm",0.15,0.05)))))*IF(OR(B3="Occ",B3="Pun"),Dashboard!V$7,IF(B3="Tit",Dashboard!W$7,Dashboard!X$7)),0))) -> 3 | G3: con Thorsvedt
A4: AKISANMIRO | B4: Scm | C4: 1 | D4: L | F4: =IF(D4<>"L","-",IF(COUNTA(P!E$2:E$1000)+COUNTA(D!E$2:E$1000)+COUNTA('C'!E$2:E$1000)+COUNTA(A!E$2:E$1000)=0,C4,ROUND(C4*MAX(0.1,IFERROR(Dashboard!B$3/Dashboard!B$10,1))*(1+Dashboard!F$7*IF(B4="Occ",0.5,IF(B4="Pun",0.35,IF(B4="Tit",0.25,IF(B4="Scm",0.15,0.05)))))*IF(OR(B4="Occ",B4="Pun"),Dashboard!V$7,IF(B4="Tit",Dashboard!W$7,Dashboard!X$7)),0))) -> 1
A5: ALAJBEGOVIC | B5: Scm | C5: 4 | D5: L | F5: =IF(D5<>"L","-",IF(COUNTA(P!E$2:E$1000)+COUNTA(D!E$2:E$1000)+COUNTA('C'!E$2:E$1000)+COUNTA(A!E$2:E$1000)=0,C5,ROUND(C5*MAX(0.1,IFERROR(Dashboard!B$3/Dashboard!B$10,1))*(1+Dashboard!F$7*IF(B5="Occ",0.5,IF(B5="Pun",0.35,IF(B5="Tit",0.25,IF(B5="Scm",0.15,0.05)))))*IF(OR(B5="Occ",B5="Pun"),Dashboard!V$7,IF(B5="Tit",Dashboard!W$7,Dashboard!X$7)),0))) -> 4
A6: ALMQVIST | B6: Scm | C6: 1 | D6: L | F6: =IF(D6<>"L","-",IF(COUNTA(P!E$2:E$1000)+COUNTA(D!E$2:E$1000)+COUNTA('C'!E$2:E$1000)+COUNTA(A!E$2:E$1000)=0,C6,ROUND(C6*MAX(0.1,IFERROR(Dashboard!B$3/Dashboard!B$10,1))*(1+Dashboard!F$7*IF(B6="Occ",0.5,IF(B6="Pun",0.35,IF(B6="Tit",0.25,IF(B6="Scm",0.15,0.05)))))*IF(OR(B6="Occ",B6="Pun"),Dashboard!V$7,IF(B6="Tit",Dashboard!W$7,Dashboard!X$7)),0))) -> 1
A7: ATTA | B7: Tit | C7: 8 | D7: L | F7: =IF(D7<>"L","-",IF(COUNTA(P!E$2:E$1000)+COUNTA(D!E$2:E$1000)+COUNTA('C'!E$2:E$1000)+COUNTA(A!E$2:E$1000)=0,C7,ROUND(C7*MAX(0.1,IFERROR(Dashboard!B$3/Dashboard!B$10,1))*(1+Dashboard!F$7*IF(B7="Occ",0.5,IF(B7="Pun",0.35,IF(B7="Tit",0.25,IF(B7="Scm",0.15,0.05)))))*IF(OR(B7="Occ",B7="Pun"),Dashboard!V$7,IF(B7="Tit",Dashboard!W$7,Dashboard!X$7)),0))) -> 8
A8: BAKOLA | B8: Tit | C8: 1 | D8: L | F8: =IF(D8<>"L","-",IF(COUNTA(P!E$2:E$1000)+COUNTA(D!E$2:E$1000)+COUNTA('C'!E$2:E$1000)+COUNTA(A!E$2:E$1000)=0,C8,ROUND(C8*MAX(0.1,IFERROR(Dashboard!B$3/Dashboard!B$10,1))*(1+Dashboard!F$7*IF(B8="Occ",0.5,IF(B8="Pun",0.35,IF(B8="Tit",0.25,IF(B8="Scm",0.15,0.05)))))*IF(OR(B8="Occ",B8="Pun"),Dashboard!V$7,IF(B8="Tit",Dashboard!W$7,Dashboard!X$7)),0))) -> 1
A9: BALDANZI | B9: Pun | C9: 15 | D9: L | F9: =IF(D9<>"L","-",IF(COUNTA(P!E$2:E$1000)+COUNTA(D!E$2:E$1000)+COUNTA('C'!E$2:E$1000)+COUNTA(A!E$2:E$1000)=0,C9,ROUND(C9*MAX(0.1,IFERROR(Dashboard!B$3/Dashboard!B$10,1))*(1+Dashboard!F$7*IF(B9="Occ",0.5,IF(B9="Pun",0.35,IF(B9="Tit",0.25,IF(B9="Scm",0.15,0.05)))))*IF(OR(B9="Occ",B9="Pun"),Dashboard!V$7,IF(B9="Tit",Dashboard!W$7,Dashboard!X$7)),0))) -> 15 | G9: Piaz.
A10: BARELLA | B10: Occ | C10: 30 | D10: L | F10: =IF(D10<>"L","-",IF(COUNTA(P!E$2:E$1000)+COUNTA(D!E$2:E$1000)+COUNTA('C'!E$2:E$1000)+COUNTA(A!E$2:E$1000)=0,C10,ROUND(C10*MAX(0.1,IFERROR(Dashboard!B$3/Dashboard!B$10,1))*(1+Dashboard!F$7*IF(B10="Occ",0.5,IF(B10="Pun",0.35,IF(B10="Tit",0.25,IF(B10="Scm",0.15,0.05)))))*IF(OR(B10="Occ",B10="Pun"),Dashboard!V$7,IF(B10="Tit",Dashboard!W$7,Dashboard!X$7)),0))) -> 30
A11: BASIC | B11: Sca | C11: 1 | D11: L | F11: =IF(D11<>"L","-",IF(COUNTA(P!E$2:E$1000)+COUNTA(D!E$2:E$1000)+COUNTA('C'!E$2:E$1000)+COUNTA(A!E$2:E$1000)=0,C11,ROUND(C11*MAX(0.1,IFERROR(Dashboard!B$3/Dashboard!B$10,1))*(1+Dashboard!F$7*IF(B11="Occ",0.5,IF(B11="Pun",0.35,IF(B11="Tit",0.25,IF(B11="Scm",0.15,0.05)))))*IF(OR(B11="Occ",B11="Pun"),Dashboard!V$7,IF(B11="Tit",Dashboard!W$7,Dashboard!X$7)),0))) -> 1
A12: BATURINA | B12: Pun | C12: 40 | D12: L | F12: =IF(D12<>"L","-",IF(COUNTA(P!E$2:E$1000)+COUNTA(D!E$2:E$1000)+COUNTA('C'!E$2:E$1000)+COUNTA(A!E$2:E$1000)=0,C12,ROUND(C12*MAX(0.1,IFERROR(Dashboard!B$3/Dashboard!B$10,1))*(1+Dashboard!F$7*IF(B12="Occ",0.5,IF(B12="Pun",0.35,IF(B12="Tit",0.25,IF(B12="Scm",0.15,0.05)))))*IF(OR(B12="Occ",B12="Pun"),Dashboard!V$7,IF(B12="Tit",Dashboard!W$7,Dashboard!X$7)),0))) -> 40
A13: BERISHA | B13: Scm | C13: 1 | D13: L | F13: =IF(D13<>"L","-",IF(COUNTA(P!E$2:E$1000)+COUNTA(D!E$2:E$1000)+COUNTA('C'!E$2:E$1000)+COUNTA(A!E$2:E$1000)=0,C13,ROUND(C13*MAX(0.1,IFERROR(Dashboard!B$3/Dashboard!B$10,1))*(1+Dashboard!F$7*IF(B13="Occ",0.5,IF(B13="Pun",0.35,IF(B13="Tit",0.25,IF(B13="Scm",0.15,0.05)))))*IF(OR(B13="Occ",B13="Pun"),Dashboard!V$7,IF(B13="Tit",Dashboard!W$7,Dashboard!X$7)),0))) -> 1
A14: BERNABE' | B14: Tit | C14: 8 | D14: L | F14: =IF(D14<>"L","-",IF(COUNTA(P!E$2:E$1000)+COUNTA(D!E$2:E$1000)+COUNTA('C'!E$2:E$1000)+COUNTA(A!E$2:E$1000)=0,C14,ROUND(C14*MAX(0.1,IFERROR(Dashboard!B$3/Dashboard!B$10,1))*(1+Dashboard!F$7*IF(B14="Occ",0.5,IF(B14="Pun",0.35,IF(B14="Tit",0.25,IF(B14="Scm",0.15,0.05)))))*IF(OR(B14="Occ",B14="Pun"),Dashboard!V$7,IF(B14="Tit",Dashboard!W$7,Dashboard!X$7)),0))) -> 8 | G14: Piaz.
A15: BERNARDESCHI | B15: Pun | C15: 15 | D15: L | F15: =IF(D15<>"L","-",IF(COUNTA(P!E$2:E$1000)+COUNTA(D!E$2:E$1000)+COUNTA('C'!E$2:E$1000)+COUNTA(A!E$2:E$1000)=0,C15,ROUND(C15*MAX(0.1,IFERROR(Dashboard!B$3/Dashboard!B$10,1))*(1+Dashboard!F$7*IF(B15="Occ",0.5,IF(B15="Pun",0.35,IF(B15="Tit",0.25,IF(B15="Scm",0.15,0.05)))))*IF(OR(B15="Occ",B15="Pun"),Dashboard!V$7,IF(B15="Tit",Dashboard!W$7,Dashboard!X$7)),0))) -> 15 | G15: con Odgaard, Piaz.
A16: BRESCIANINI | B16: Sca | C16: 1 | D16: L | F16: =IF(D16<>"L","-",IF(COUNTA(P!E$2:E$1000)+COUNTA(D!E$2:E$1000)+COUNTA('C'!E$2:E$1000)+COUNTA(A!E$2:E$1000)=0,C16,ROUND(C16*MAX(0.1,IFERROR(Dashboard!B$3/Dashboard!B$10,1))*(1+Dashboard!F$7*IF(B16="Occ",0.5,IF(B16="Pun",0.35,IF(B16="Tit",0.25,IF(B16="Scm",0.15,0.05)))))*IF(OR(B16="Occ",B16="Pun"),Dashboard!V$7,IF(B16="Tit",Dashboard!W$7,Dashboard!X$7)),0))) -> 1
A17: BUSIO | B17: Pun | C17: 6 | D17: L | F17: =IF(D17<>"L","-",IF(COUNTA(P!E$2:E$1000)+COUNTA(D!E$2:E$1000)+COUNTA('C'!E$2:E$1000)+COUNTA(A!E$2:E$1000)=0,C17,ROUND(C17*MAX(0.1,IFERROR(Dashboard!B$3/Dashboard!B$10,1))*(1+Dashboard!F$7*IF(B17="Occ",0.5,IF(B17="Pun",0.35,IF(B17="Tit",0.25,IF(B17="Scm",0.15,0.05)))))*IF(OR(B17="Occ",B17="Pun"),Dashboard!V$7,IF(B17="Tit",Dashboard!W$7,Dashboard!X$7)),0))) -> 6
A18: CACCIAMANI | B18: Scm | C18: 1 | D18: L | F18: =IF(D18<>"L","-",IF(COUNTA(P!E$2:E$1000)+COUNTA(D!E$2:E$1000)+COUNTA('C'!E$2:E$1000)+COUNTA(A!E$2:E$1000)=0,C18,ROUND(C18*MAX(0.1,IFERROR(Dashboard!B$3/Dashboard!B$10,1))*(1+Dashboard!F$7*IF(B18="Occ",0.5,IF(B18="Pun",0.35,IF(B18="Tit",0.25,IF(B18="Scm",0.15,0.05)))))*IF(OR(B18="Occ",B18="Pun"),Dashboard!V$7,IF(B18="Tit",Dashboard!W$7,Dashboard!X$7)),0))) -> 1
A19: CALHANOGLU | B19: Occ | C19: 65 | D19: L | F19: =IF(D19<>"L","-",IF(COUNTA(P!E$2:E$1000)+COUNTA(D!E$2:E$1000)+COUNTA('C'!E$2:E$1000)+COUNTA(A!E$2:E$1000)=0,C19,ROUND(C19*MAX(0.1,IFERROR(Dashboard!B$3/Dashboard!B$10,1))*(1+Dashboard!F$7*IF(B19="Occ",0.5,IF(B19="Pun",0.35,IF(B19="Tit",0.25,IF(B19="Scm",0.15,0.05)))))*IF(OR(B19="Occ",B19="Pun"),Dashboard!V$7,IF(B19="Tit",Dashboard!W$7,Dashboard!X$7)),0))) -> 65 | G19: Rig., Piaz.
A20: CALO' | B20: Tit | C20: 8 | D20: L | F20: =IF(D20<>"L","-",IF(COUNTA(P!E$2:E$1000)+COUNTA(D!E$2:E$1000)+COUNTA('C'!E$2:E$1000)+COUNTA(A!E$2:E$1000)=0,C20,ROUND(C20*MAX(0.1,IFERROR(Dashboard!B$3/Dashboard!B$10,1))*(1+Dashboard!F$7*IF(B20="Occ",0.5,IF(B20="Pun",0.35,IF(B20="Tit",0.25,IF(B20="Scm",0.15,0.05)))))*IF(OR(B20="Occ",B20="Pun"),Dashboard!V$7,IF(B20="Tit",Dashboard!W$7,Dashboard!X$7)),0))) -> 8 | G20: Rig., Piaz.
A21: CAMBIAGHI | B21: Pun | C21: 8 | D21: L | F21: =IF(D21<>"L","-",IF(COUNTA(P!E$2:E$1000)+COUNTA(D!E$2:E$1000)+COUNTA('C'!E$2:E$1000)+COUNTA(A!E$2:E$1000)=0,C21,ROUND(C21*MAX(0.1,IFERROR(Dashboard!B$3/Dashboard!B$10,1))*(1+Dashboard!F$7*IF(B21="Occ",0.5,IF(B21="Pun",0.35,IF(B21="Tit",0.25,IF(B21="Scm",0.15,0.05)))))*IF(OR(B21="Occ",B21="Pun"),Dashboard!V$7,IF(B21="Tit",Dashboard!W$7,Dashboard!X$7)),0))) -> 8
A22: CANCELLIERI | B22: Pun | C22: 18 | D22: L | F22: =IF(D22<>"L","-",IF(COUNTA(P!E$2:E$1000)+COUNTA(D!E$2:E$1000)+COUNTA('C'!E$2:E$1000)+COUNTA(A!E$2:E$1000)=0,C22,ROUND(C22*MAX(0.1,IFERROR(Dashboard!B$3/Dashboard!B$10,1))*(1+Dashboard!F$7*IF(B22="Occ",0.5,IF(B22="Pun",0.35,IF(B22="Tit",0.25,IF(B22="Scm",0.15,0.05)))))*IF(OR(B22="Occ",B22="Pun"),Dashboard!V$7,IF(B22="Tit",Dashboard!W$7,Dashboard!X$7)),0))) -> 18
A23: CASADEI | B23: Scm | C23: 1 | D23: L | F23: =IF(D23<>"L","-",IF(COUNTA(P!E$2:E$1000)+COUNTA(D!E$2:E$1000)+COUNTA('C'!E$2:E$1000)+COUNTA(A!E$2:E$1000)=0,C23,ROUND(C23*MAX(0.1,IFERROR(Dashboard!B$3/Dashboard!B$10,1))*(1+Dashboard!F$7*IF(B23="Occ",0.5,IF(B23="Pun",0.35,IF(B23="Tit",0.25,IF(B23="Scm",0.15,0.05)))))*IF(OR(B23="Occ",B23="Pun"),Dashboard!V$7,IF(B23="Tit",Dashboard!W$7,Dashboard!X$7)),0))) -> 1
A24: CHUKWUEZE | B24: Scm | C24: 3 | D24: L | F24: =IF(D24<>"L","-",IF(COUNTA(P!E$2:E$1000)+COUNTA(D!E$2:E$1000)+COUNTA('C'!E$2:E$1000)+COUNTA(A!E$2:E$1000)=0,C24,ROUND(C24*MAX(0.1,IFERROR(Dashboard!B$3/Dashboard!B$10,1))*(1+Dashboard!F$7*IF(B24="Occ",0.5,IF(B24="Pun",0.35,IF(B24="Tit",0.25,IF(B24="Scm",0.15,0.05)))))*IF(OR(B24="Occ",B24="Pun"),Dashboard!V$7,IF(B24="Tit",Dashboard!W$7,Dashboard!X$7)),0))) -> 3 | G24: solo con Saelemakers
A25: CICHELLA | B25: Sca | C25: 1 | D25: L | F25: =IF(D25<>"L","-",IF(COUNTA(P!E$2:E$1000)+COUNTA(D!E$2:E$1000)+COUNTA('C'!E$2:E$1000)+COUNTA(A!E$2:E$1000)=0,C25,ROUND(C25*MAX(0.1,IFERROR(Dashboard!B$3/Dashboard!B$10,1))*(1+Dashboard!F$7*IF(B25="Occ",0.5,IF(B25="Pun",0.35,IF(B25="Tit",0.25,IF(B25="Scm",0.15,0.05)))))*IF(OR(B25="Occ",B25="Pun"),Dashboard!V$7,IF(B25="Tit",Dashboard!W$7,Dashboard!X$7)),0))) -> 1
A26: CISSE' A. | B26: Scm | C26: 4 | D26: L | F26: =IF(D26<>"L","-",IF(COUNTA(P!E$2:E$1000)+COUNTA(D!E$2:E$1000)+COUNTA('C'!E$2:E$1000)+COUNTA(A!E$2:E$1000)=0,C26,ROUND(C26*MAX(0.1,IFERROR(Dashboard!B$3/Dashboard!B$10,1))*(1+Dashboard!F$7*IF(B26="Occ",0.5,IF(B26="Pun",0.35,IF(B26="Tit",0.25,IF(B26="Scm",0.15,0.05)))))*IF(OR(B26="Occ",B26="Pun"),Dashboard!V$7,IF(B26="Tit",Dashboard!W$7,Dashboard!X$7)),0))) -> 4
A27: COLPANI | B27: Pun | C27: 8 | D27: L | F27: =IF(D27<>"L","-",IF(COUNTA(P!E$2:E$1000)+COUNTA(D!E$2:E$1000)+COUNTA('C'!E$2:E$1000)+COUNTA(A!E$2:E$1000)=0,C27,ROUND(C27*MAX(0.1,IFERROR(Dashboard!B$3/Dashboard!B$10,1))*(1+Dashboard!F$7*IF(B27="Occ",0.5,IF(B27="Pun",0.35,IF(B27="Tit",0.25,IF(B27="Scm",0.15,0.05)))))*IF(OR(B27="Occ",B27="Pun"),Dashboard!V$7,IF(B27="Tit",Dashboard!W$7,Dashboard!X$7)),0))) -> 8 | G27: Piaz.
A28: CONCEICAO | B28: Pun | C28: 20 | D28: L | F28: =IF(D28<>"L","-",IF(COUNTA(P!E$2:E$1000)+COUNTA(D!E$2:E$1000)+COUNTA('C'!E$2:E$1000)+COUNTA(A!E$2:E$1000)=0,C28,ROUND(C28*MAX(0.1,IFERROR(Dashboard!B$3/Dashboard!B$10,1))*(1+Dashboard!F$7*IF(B28="Occ",0.5,IF(B28="Pun",0.35,IF(B28="Tit",0.25,IF(B28="Scm",0.15,0.05)))))*IF(OR(B28="Occ",B28="Pun"),Dashboard!V$7,IF(B28="Tit",Dashboard!W$7,Dashboard!X$7)),0))) -> 20
A29: CRISTANTE | B29: Tit | C29: 5 | D29: L | F29: =IF(D29<>"L","-",IF(COUNTA(P!E$2:E$1000)+COUNTA(D!E$2:E$1000)+COUNTA('C'!E$2:E$1000)+COUNTA(A!E$2:E$1000)=0,C29,ROUND(C29*MAX(0.1,IFERROR(Dashboard!B$3/Dashboard!B$10,1))*(1+Dashboard!F$7*IF(B29="Occ",0.5,IF(B29="Pun",0.35,IF(B29="Tit",0.25,IF(B29="Scm",0.15,0.05)))))*IF(OR(B29="Occ",B29="Pun"),Dashboard!V$7,IF(B29="Tit",Dashboard!W$7,Dashboard!X$7)),0))) -> 5
A30: DA CUNHA | B30: Tit | C30: 7 | D30: L | F30: =IF(D30<>"L","-",IF(COUNTA(P!E$2:E$1000)+COUNTA(D!E$2:E$1000)+COUNTA('C'!E$2:E$1000)+COUNTA(A!E$2:E$1000)=0,C30,ROUND(C30*MAX(0.1,IFERROR(Dashboard!B$3/Dashboard!B$10,1))*(1+Dashboard!F$7*IF(B30="Occ",0.5,IF(B30="Pun",0.35,IF(B30="Tit",0.25,IF(B30="Scm",0.15,0.05)))))*IF(OR(B30="Occ",B30="Pun"),Dashboard!V$7,IF(B30="Tit",Dashboard!W$7,Dashboard!X$7)),0))) -> 7 | G30: Rig.
A31: DE BRUYNE | B31: Occ | C31: 18 | D31: L | F31: =IF(D31<>"L","-",IF(COUNTA(P!E$2:E$1000)+COUNTA(D!E$2:E$1000)+COUNTA('C'!E$2:E$1000)+COUNTA(A!E$2:E$1000)=0,C31,ROUND(C31*MAX(0.1,IFERROR(Dashboard!B$3/Dashboard!B$10,1))*(1+Dashboard!F$7*IF(B31="Occ",0.5,IF(B31="Pun",0.35,IF(B31="Tit",0.25,IF(B31="Scm",0.15,0.05)))))*IF(OR(B31="Occ",B31="Pun"),Dashboard!V$7,IF(B31="Tit",Dashboard!W$7,Dashboard!X$7)),0))) -> 18 | G31: Rig., Piaz.
A32: DIOUF | B32: Pun | C32: 5 | D32: L | F32: =IF(D32<>"L","-",IF(COUNTA(P!E$2:E$1000)+COUNTA(D!E$2:E$1000)+COUNTA('C'!E$2:E$1000)+COUNTA(A!E$2:E$1000)=0,C32,ROUND(C32*MAX(0.1,IFERROR(Dashboard!B$3/Dashboard!B$10,1))*(1+Dashboard!F$7*IF(B32="Occ",0.5,IF(B32="Pun",0.35,IF(B32="Tit",0.25,IF(B32="Scm",0.15,0.05)))))*IF(OR(B32="Occ",B32="Pun"),Dashboard!V$7,IF(B32="Tit",Dashboard!W$7,Dashboard!X$7)),0))) -> 5 | G32: se coperti
A33: DOMINGUEZ B. | B33: Scm | C33: 3 | D33: L | F33: =IF(D33<>"L","-",IF(COUNTA(P!E$2:E$1000)+COUNTA(D!E$2:E$1000)+COUNTA('C'!E$2:E$1000)+COUNTA(A!E$2:E$1000)=0,C33,ROUND(C33*MAX(0.1,IFERROR(Dashboard!B$3/Dashboard!B$10,1))*(1+Dashboard!F$7*IF(B33="Occ",0.5,IF(B33="Pun",0.35,IF(B33="Tit",0.25,IF(B33="Scm",0.15,0.05)))))*IF(OR(B33="Occ",B33="Pun"),Dashboard!V$7,IF(B33="Tit",Dashboard!W$7,Dashboard!X$7)),0))) -> 3
A34: DOUGLAS LUIZ | B34: Tit | C34: 1 | D34: L | F34: =IF(D34<>"L","-",IF(COUNTA(P!E$2:E$1000)+COUNTA(D!E$2:E$1000)+COUNTA('C'!E$2:E$1000)+COUNTA(A!E$2:E$1000)=0,C34,ROUND(C34*MAX(0.1,IFERROR(Dashboard!B$3/Dashboard!B$10,1))*(1+Dashboard!F$7*IF(B34="Occ",0.5,IF(B34="Pun",0.35,IF(B34="Tit",0.25,IF(B34="Scm",0.15,0.05)))))*IF(OR(B34="Occ",B34="Pun"),Dashboard!V$7,IF(B34="Tit",Dashboard!W$7,Dashboard!X$7)),0))) -> 1
A35: EDERSON | B35: Pun | C35: 13 | D35: L | F35: =IF(D35<>"L","-",IF(COUNTA(P!E$2:E$1000)+COUNTA(D!E$2:E$1000)+COUNTA('C'!E$2:E$1000)+COUNTA(A!E$2:E$1000)=0,C35,ROUND(C35*MAX(0.1,IFERROR(Dashboard!B$3/Dashboard!B$10,1))*(1+Dashboard!F$7*IF(B35="Occ",0.5,IF(B35="Pun",0.35,IF(B35="Tit",0.25,IF(B35="Scm",0.15,0.05)))))*IF(OR(B35="Occ",B35="Pun"),Dashboard!V$7,IF(B35="Tit",Dashboard!W$7,Dashboard!X$7)),0))) -> 13
A36: EKKELENKAMP | B36: Pun | C36: 13 | D36: L | F36: =IF(D36<>"L","-",IF(COUNTA(P!E$2:E$1000)+COUNTA(D!E$2:E$1000)+COUNTA('C'!E$2:E$1000)+COUNTA(A!E$2:E$1000)=0,C36,ROUND(C36*MAX(0.1,IFERROR(Dashboard!B$3/Dashboard!B$10,1))*(1+Dashboard!F$7*IF(B36="Occ",0.5,IF(B36="Pun",0.35,IF(B36="Tit",0.25,IF(B36="Scm",0.15,0.05)))))*IF(OR(B36="Occ",B36="Pun"),Dashboard!V$7,IF(B36="Tit",Dashboard!W$7,Dashboard!X$7)),0))) -> 13
A37: EL AZZOUZI | B37: Sca | C37: 1 | D37: L | F37: =IF(D37<>"L","-",IF(COUNTA(P!E$2:E$1000)+COUNTA(D!E$2:E$1000)+COUNTA('C'!E$2:E$1000)+COUNTA(A!E$2:E$1000)=0,C37,ROUND(C37*MAX(0.1,IFERROR(Dashboard!B$3/Dashboard!B$10,1))*(1+Dashboard!F$7*IF(B37="Occ",0.5,IF(B37="Pun",0.35,IF(B37="Tit",0.25,IF(B37="Scm",0.15,0.05)))))*IF(OR(B37="Occ",B37="Pun"),Dashboard!V$7,IF(B37="Tit",Dashboard!W$7,Dashboard!X$7)),0))) -> 1
A38: ELLERTSSON | B38: Pun | C38: 8 | D38: L | F38: =IF(D38<>"L","-",IF(COUNTA(P!E$2:E$1000)+COUNTA(D!E$2:E$1000)+COUNTA('C'!E$2:E$1000)+COUNTA(A!E$2:E$1000)=0,C38,ROUND(C38*MAX(0.1,IFERROR(Dashboard!B$3/Dashboard!B$10,1))*(1+Dashboard!F$7*IF(B38="Occ",0.5,IF(B38="Pun",0.35,IF(B38="Tit",0.25,IF(B38="Scm",0.15,0.05)))))*IF(OR(B38="Occ",B38="Pun"),Dashboard!V$7,IF(B38="Tit",Dashboard!W$7,Dashboard!X$7)),0))) -> 8
A39: ELMAS | B39: Scm | C39: 1 | D39: L | F39: =IF(D39<>"L","-",IF(COUNTA(P!E$2:E$1000)+COUNTA(D!E$2:E$1000)+COUNTA('C'!E$2:E$1000)+COUNTA(A!E$2:E$1000)=0,C39,ROUND(C39*MAX(0.1,IFERROR(Dashboard!B$3/Dashboard!B$10,1))*(1+Dashboard!F$7*IF(B39="Occ",0.5,IF(B39="Pun",0.35,IF(B39="Tit",0.25,IF(B39="Scm",0.15,0.05)))))*IF(OR(B39="Occ",B39="Pun"),Dashboard!V$7,IF(B39="Tit",Dashboard!W$7,Dashboard!X$7)),0))) -> 1 | G39: se coperti
A40: FAGIOLI | B40: Tit | C40: 3 | D40: L | F40: =IF(D40<>"L","-",IF(COUNTA(P!E$2:E$1000)+COUNTA(D!E$2:E$1000)+COUNTA('C'!E$2:E$1000)+COUNTA(A!E$2:E$1000)=0,C40,ROUND(C40*MAX(0.1,IFERROR(Dashboard!B$3/Dashboard!B$10,1))*(1+Dashboard!F$7*IF(B40="Occ",0.5,IF(B40="Pun",0.35,IF(B40="Tit",0.25,IF(B40="Scm",0.15,0.05)))))*IF(OR(B40="Occ",B40="Pun"),Dashboard!V$7,IF(B40="Tit",Dashboard!W$7,Dashboard!X$7)),0))) -> 3
...

Sheet A
A1: NOME | B1: CAT | C1: MAX | D1: STATO | E1: COSTO_REALE | F1: MAX_D | G1: NOTE
A2: ADAMS A. | B2: Sca | C2: 1 | D2: L | F2: =IF(D2<>"L","-",IF(COUNTA(P!E$2:E$1000)+COUNTA(D!E$2:E$1000)+COUNTA('C'!E$2:E$1000)+COUNTA(A!E$2:E$1000)=0,C2,ROUND(C2*MAX(0.1,IFERROR(Dashboard!B$3/Dashboard!B$10,1))*(1+Dashboard!F$8*IF(B2="Occ",0.5,IF(B2="Pun",0.35,IF(B2="Tit",0.25,IF(B2="Scm",0.15,0.05))))),0))) -> 1
A3: ADAMS C. | B3: Scm | C3: 1 | D3: L | F3: =IF(D3<>"L","-",IF(COUNTA(P!E$2:E$1000)+COUNTA(D!E$2:E$1000)+COUNTA('C'!E$2:E$1000)+COUNTA(A!E$2:E$1000)=0,C3,ROUND(C3*MAX(0.1,IFERROR(Dashboard!B$3/Dashboard!B$10,1))*(1+Dashboard!F$8*IF(B3="Occ",0.5,IF(B3="Pun",0.35,IF(B3="Tit",0.25,IF(B3="Scm",0.15,0.05))))),0))) -> 1
A4: BERARDI | B4: Pun | C4: 65 | D4: L | F4: =IF(D4<>"L","-",IF(COUNTA(P!E$2:E$1000)+COUNTA(D!E$2:E$1000)+COUNTA('C'!E$2:E$1000)+COUNTA(A!E$2:E$1000)=0,C4,ROUND(C4*MAX(0.1,IFERROR(Dashboard!B$3/Dashboard!B$10,1))*(1+Dashboard!F$8*IF(B4="Occ",0.5,IF(B4="Pun",0.35,IF(B4="Tit",0.25,IF(B4="Scm",0.15,0.05))))),0))) -> 65 | G4: Rischio Inf., Rig., Piaz.
A5: BOGA | B5: Scm | C5: 10 | D5: L | F5: =IF(D5<>"L","-",IF(COUNTA(P!E$2:E$1000)+COUNTA(D!E$2:E$1000)+COUNTA('C'!E$2:E$1000)+COUNTA(A!E$2:E$1000)=0,C5,ROUND(C5*MAX(0.1,IFERROR(Dashboard!B$3/Dashboard!B$10,1))*(1+Dashboard!F$8*IF(B5="Occ",0.5,IF(B5="Pun",0.35,IF(B5="Tit",0.25,IF(B5="Scm",0.15,0.05))))),0))) -> 10
A6: BONNY | B6: Scm | C6: 20 | D6: L | F6: =IF(D6<>"L","-",IF(COUNTA(P!E$2:E$1000)+COUNTA(D!E$2:E$1000)+COUNTA('C'!E$2:E$1000)+COUNTA(A!E$2:E$1000)=0,C6,ROUND(C6*MAX(0.1,IFERROR(Dashboard!B$3/Dashboard!B$10,1))*(1+Dashboard!F$8*IF(B6="Occ",0.5,IF(B6="Pun",0.35,IF(B6="Tit",0.25,IF(B6="Scm",0.15,0.05))))),0))) -> 20
A7: BOWIE | B7: Pun | C7: 15 | D7: L | F7: =IF(D7<>"L","-",IF(COUNTA(P!E$2:E$1000)+COUNTA(D!E$2:E$1000)+COUNTA('C'!E$2:E$1000)+COUNTA(A!E$2:E$1000)=0,C7,ROUND(C7*MAX(0.1,IFERROR(Dashboard!B$3/Dashboard!B$10,1))*(1+Dashboard!F$8*IF(B7="Occ",0.5,IF(B7="Pun",0.35,IF(B7="Tit",0.25,IF(B7="Scm",0.15,0.05))))),0))) -> 15
A8: CAMARDA | B8: Sca | C8: 1 | D8: L | F8: =IF(D8<>"L","-",IF(COUNTA(P!E$2:E$1000)+COUNTA(D!E$2:E$1000)+COUNTA('C'!E$2:E$1000)+COUNTA(A!E$2:E$1000)=0,C8,ROUND(C8*MAX(0.1,IFERROR(Dashboard!B$3/Dashboard!B$10,1))*(1+Dashboard!F$8*IF(B8="Occ",0.5,IF(B8="Pun",0.35,IF(B8="Tit",0.25,IF(B8="Scm",0.15,0.05))))),0))) -> 1
A9: CASTRO | B9: Occ | C9: 50 | D9: L | F9: =IF(D9<>"L","-",IF(COUNTA(P!E$2:E$1000)+COUNTA(D!E$2:E$1000)+COUNTA('C'!E$2:E$1000)+COUNTA(A!E$2:E$1000)=0,C9,ROUND(C9*MAX(0.1,IFERROR(Dashboard!B$3/Dashboard!B$10,1))*(1+Dashboard!F$8*IF(B9="Occ",0.5,IF(B9="Pun",0.35,IF(B9="Tit",0.25,IF(B9="Scm",0.15,0.05))))),0))) -> 50 | G9: con Malen (pref.)
A10: COLOMBO | B10: Pun | C10: 30 | D10: L | F10: =IF(D10<>"L","-",IF(COUNTA(P!E$2:E$1000)+COUNTA(D!E$2:E$1000)+COUNTA('C'!E$2:E$1000)+COUNTA(A!E$2:E$1000)=0,C10,ROUND(C10*MAX(0.1,IFERROR(Dashboard!B$3/Dashboard!B$10,1))*(1+Dashboard!F$8*IF(B10="Occ",0.5,IF(B10="Pun",0.35,IF(B10="Tit",0.25,IF(B10="Scm",0.15,0.05))))),0))) -> 30 | G10: Rig.
A11: CUTRONE | B11: Sca | C11: 5 | D11: L | F11: =IF(D11<>"L","-",IF(COUNTA(P!E$2:E$1000)+COUNTA(D!E$2:E$1000)+COUNTA('C'!E$2:E$1000)+COUNTA(A!E$2:E$1000)=0,C11,ROUND(C11*MAX(0.1,IFERROR(Dashboard!B$3/Dashboard!B$10,1))*(1+Dashboard!F$8*IF(B11="Occ",0.5,IF(B11="Pun",0.35,IF(B11="Tit",0.25,IF(B11="Scm",0.15,0.05))))),0))) -> 5
A12: DAVIES K. | B12: Pun | C12: 60 | D12: L | F12: =IF(D12<>"L","-",IF(COUNTA(P!E$2:E$1000)+COUNTA(D!E$2:E$1000)+COUNTA('C'!E$2:E$1000)+COUNTA(A!E$2:E$1000)=0,C12,ROUND(C12*MAX(0.1,IFERROR(Dashboard!B$3/Dashboard!B$10,1))*(1+Dashboard!F$8*IF(B12="Occ",0.5,IF(B12="Pun",0.35,IF(B12="Tit",0.25,IF(B12="Scm",0.15,0.05))))),0))) -> 60 | G12: Rischio Inf., Rig.
A13: DE KETELAERE | B13: Pun | C13: 50 | D13: L | F13: =IF(D13<>"L","-",IF(COUNTA(P!E$2:E$1000)+COUNTA(D!E$2:E$1000)+COUNTA('C'!E$2:E$1000)+COUNTA(A!E$2:E$1000)=0,C13,ROUND(C13*MAX(0.1,IFERROR(Dashboard!B$3/Dashboard!B$10,1))*(1+Dashboard!F$8*IF(B13="Occ",0.5,IF(B13="Pun",0.35,IF(B13="Tit",0.25,IF(B13="Scm",0.15,0.05))))),0))) -> 50 | G13: Piaz.
A14: DIA | B14: Tit | C14: 40 | D14: L | F14: =IF(D14<>"L","-",IF(COUNTA(P!E$2:E$1000)+COUNTA(D!E$2:E$1000)+COUNTA('C'!E$2:E$1000)+COUNTA(A!E$2:E$1000)=0,C14,ROUND(C14*MAX(0.1,IFERROR(Dashboard!B$3/Dashboard!B$10,1))*(1+Dashboard!F$8*IF(B14="Occ",0.5,IF(B14="Pun",0.35,IF(B14="Tit",0.25,IF(B14="Scm",0.15,0.05))))),0))) -> 40
A15: DIAO | B15: Sca | C15: 25 | D15: L | F15: =IF(D15<>"L","-",IF(COUNTA(P!E$2:E$1000)+COUNTA(D!E$2:E$1000)+COUNTA('C'!E$2:E$1000)+COUNTA(A!E$2:E$1000)=0,C15,ROUND(C15*MAX(0.1,IFERROR(Dashboard!B$3/Dashboard!B$10,1))*(1+Dashboard!F$8*IF(B15="Occ",0.5,IF(B15="Pun",0.35,IF(B15="Tit",0.25,IF(B15="Scm",0.15,0.05))))),0))) -> 25
A16: DOUVIKAS | B16: Pun | C16: 70 | D16: L | F16: =IF(D16<>"L","-",IF(COUNTA(P!E$2:E$1000)+COUNTA(D!E$2:E$1000)+COUNTA('C'!E$2:E$1000)+COUNTA(A!E$2:E$1000)=0,C16,ROUND(C16*MAX(0.1,IFERROR(Dashboard!B$3/Dashboard!B$10,1))*(1+Dashboard!F$8*IF(B16="Occ",0.5,IF(B16="Pun",0.35,IF(B16="Tit",0.25,IF(B16="Scm",0.15,0.05))))),0))) -> 70
A17: DOVBYK | B17: Tit | C17: 30 | D17: L | F17: =IF(D17<>"L","-",IF(COUNTA(P!E$2:E$1000)+COUNTA(D!E$2:E$1000)+COUNTA('C'!E$2:E$1000)+COUNTA(A!E$2:E$1000)=0,C17,ROUND(C17*MAX(0.1,IFERROR(Dashboard!B$3/Dashboard!B$10,1))*(1+Dashboard!F$8*IF(B17="Occ",0.5,IF(B17="Pun",0.35,IF(B17="Tit",0.25,IF(B17="Scm",0.15,0.05))))),0))) -> 30
A18: DYBALA | B18: Pun | C18: 70 | D18: L | F18: =IF(D18<>"L","-",IF(COUNTA(P!E$2:E$1000)+COUNTA(D!E$2:E$1000)+COUNTA('C'!E$2:E$1000)+COUNTA(A!E$2:E$1000)=0,C18,ROUND(C18*MAX(0.1,IFERROR(Dashboard!B$3/Dashboard!B$10,1))*(1+Dashboard!F$8*IF(B18="Occ",0.5,IF(B18="Pun",0.35,IF(B18="Tit",0.25,IF(B18="Scm",0.15,0.05))))),0))) -> 70 | G18: Rischio Inf., Piaz.
A19: ELPHEGE | B19: Scm | C19: 1 | D19: L | F19: =IF(D19<>"L","-",IF(COUNTA(P!E$2:E$1000)+COUNTA(D!E$2:E$1000)+COUNTA('C'!E$2:E$1000)+COUNTA(A!E$2:E$1000)=0,C19,ROUND(C19*MAX(0.1,IFERROR(Dashboard!B$3/Dashboard!B$10,1))*(1+Dashboard!F$8*IF(B19="Occ",0.5,IF(B19="Pun",0.35,IF(B19="Tit",0.25,IF(B19="Scm",0.15,0.05))))),0))) -> 1
A20: ESPOSITO F. P. | B20: Pun | C20: 60 | D20: L | F20: =IF(D20<>"L","-",IF(COUNTA(P!E$2:E$1000)+COUNTA(D!E$2:E$1000)+COUNTA('C'!E$2:E$1000)+COUNTA(A!E$2:E$1000)=0,C20,ROUND(C20*MAX(0.1,IFERROR(Dashboard!B$3/Dashboard!B$10,1))*(1+Dashboard!F$8*IF(B20="Occ",0.5,IF(B20="Pun",0.35,IF(B20="Tit",0.25,IF(B20="Scm",0.15,0.05))))),0))) -> 60
A21: GEUBBELS | B21: Sca | C21: 5 | D21: L | F21: =IF(D21<>"L","-",IF(COUNTA(P!E$2:E$1000)+COUNTA(D!E$2:E$1000)+COUNTA('C'!E$2:E$1000)+COUNTA(A!E$2:E$1000)=0,C21,ROUND(C21*MAX(0.1,IFERROR(Dashboard!B$3/Dashboard!B$10,1))*(1+Dashboard!F$8*IF(B21="Occ",0.5,IF(B21="Pun",0.35,IF(B21="Tit",0.25,IF(B21="Scm",0.15,0.05))))),0))) -> 5 | G21: Rig.
A22: GIMENEZ | B22: Sca | C22: 1 | D22: L | F22: =IF(D22<>"L","-",IF(COUNTA(P!E$2:E$1000)+COUNTA(D!E$2:E$1000)+COUNTA('C'!E$2:E$1000)+COUNTA(A!E$2:E$1000)=0,C22,ROUND(C22*MAX(0.1,IFERROR(Dashboard!B$3/Dashboard!B$10,1))*(1+Dashboard!F$8*IF(B22="Occ",0.5,IF(B22="Pun",0.35,IF(B22="Tit",0.25,IF(B22="Scm",0.15,0.05))))),0))) -> 1 | G22: con Ramos G.
A23: HOJLUND | B23: Pun | C23: 70 | D23: L | F23: =IF(D23<>"L","-",IF(COUNTA(P!E$2:E$1000)+COUNTA(D!E$2:E$1000)+COUNTA('C'!E$2:E$1000)+COUNTA(A!E$2:E$1000)=0,C23,ROUND(C23*MAX(0.1,IFERROR(Dashboard!B$3/Dashboard!B$10,1))*(1+Dashboard!F$8*IF(B23="Occ",0.5,IF(B23="Pun",0.35,IF(B23="Tit",0.25,IF(B23="Scm",0.15,0.05))))),0))) -> 70
A24: KEAN | B24: Occ | C24: 120 | D24: L | F24: =IF(D24<>"L","-",IF(COUNTA(P!E$2:E$1000)+COUNTA(D!E$2:E$1000)+COUNTA('C'!E$2:E$1000)+COUNTA(A!E$2:E$1000)=0,C24,ROUND(C24*MAX(0.1,IFERROR(Dashboard!B$3/Dashboard!B$10,1))*(1+Dashboard!F$8*IF(B24="Occ",0.5,IF(B24="Pun",0.35,IF(B24="Tit",0.25,IF(B24="Scm",0.15,0.05))))),0))) -> 120
A25: KEVIN CARLOS | B25: Sca | C25: 25 | D25: L | F25: =IF(D25<>"L","-",IF(COUNTA(P!E$2:E$1000)+COUNTA(D!E$2:E$1000)+COUNTA('C'!E$2:E$1000)+COUNTA(A!E$2:E$1000)=0,C25,ROUND(C25*MAX(0.1,IFERROR(Dashboard!B$3/Dashboard!B$10,1))*(1+Dashboard!F$8*IF(B25="Occ",0.5,IF(B25="Pun",0.35,IF(B25="Tit",0.25,IF(B25="Scm",0.15,0.05))))),0))) -> 25 | G25: Rig.
A26: KOLO MUANI | B26: Pun | C26: 230 | D26: L | F26: =IF(D26<>"L","-",IF(COUNTA(P!E$2:E$1000)+COUNTA(D!E$2:E$1000)+COUNTA('C'!E$2:E$1000)+COUNTA(A!E$2:E$1000)=0,C26,ROUND(C26*MAX(0.1,IFERROR(Dashboard!B$3/Dashboard!B$10,1))*(1+Dashboard!F$8*IF(B26="Occ",0.5,IF(B26="Pun",0.35,IF(B26="Tit",0.25,IF(B26="Scm",0.15,0.05))))),0))) -> 230 | G26: Rig.
A27: KRSTOVIC | B27: Pun | C27: 65 | D27: L | F27: =IF(D27<>"L","-",IF(COUNTA(P!E$2:E$1000)+COUNTA(D!E$2:E$1000)+COUNTA('C'!E$2:E$1000)+COUNTA(A!E$2:E$1000)=0,C27,ROUND(C27*MAX(0.1,IFERROR(Dashboard!B$3/Dashboard!B$10,1))*(1+Dashboard!F$8*IF(B27="Occ",0.5,IF(B27="Pun",0.35,IF(B27="Tit",0.25,IF(B27="Scm",0.15,0.05))))),0))) -> 65
A28: KVERNADZE | B28: Tit | C28: 1 | D28: L | F28: =IF(D28<>"L","-",IF(COUNTA(P!E$2:E$1000)+COUNTA(D!E$2:E$1000)+COUNTA('C'!E$2:E$1000)+COUNTA(A!E$2:E$1000)=0,C28,ROUND(C28*MAX(0.1,IFERROR(Dashboard!B$3/Dashboard!B$10,1))*(1+Dashboard!F$8*IF(B28="Occ",0.5,IF(B28="Pun",0.35,IF(B28="Tit",0.25,IF(B28="Scm",0.15,0.05))))),0))) -> 1
A29: LANG | B29: Sca | C29: 1 | D29: L | F29: =IF(D29<>"L","-",IF(COUNTA(P!E$2:E$1000)+COUNTA(D!E$2:E$1000)+COUNTA('C'!E$2:E$1000)+COUNTA(A!E$2:E$1000)=0,C29,ROUND(C29*MAX(0.1,IFERROR(Dashboard!B$3/Dashboard!B$10,1))*(1+Dashboard!F$8*IF(B29="Occ",0.5,IF(B29="Pun",0.35,IF(B29="Tit",0.25,IF(B29="Scm",0.15,0.05))))),0))) -> 1
A30: LAURIENTE' | B30: Pun | C30: 40 | D30: L | F30: =IF(D30<>"L","-",IF(COUNTA(P!E$2:E$1000)+COUNTA(D!E$2:E$1000)+COUNTA('C'!E$2:E$1000)+COUNTA(A!E$2:E$1000)=0,C30,ROUND(C30*MAX(0.1,IFERROR(Dashboard!B$3/Dashboard!B$10,1))*(1+Dashboard!F$8*IF(B30="Occ",0.5,IF(B30="Pun",0.35,IF(B30="Tit",0.25,IF(B30="Scm",0.15,0.05))))),0))) -> 40
A31: LEAO | B31: Tit | C31: 50 | D31: L | F31: =IF(D31<>"L","-",IF(COUNTA(P!E$2:E$1000)+COUNTA(D!E$2:E$1000)+COUNTA('C'!E$2:E$1000)+COUNTA(A!E$2:E$1000)=0,C31,ROUND(C31*MAX(0.1,IFERROR(Dashboard!B$3/Dashboard!B$10,1))*(1+Dashboard!F$8*IF(B31="Occ",0.5,IF(B31="Pun",0.35,IF(B31="Tit",0.25,IF(B31="Scm",0.15,0.05))))),0))) -> 50
A32: LONTANI | B32: Scm | C32: 1 | D32: L | F32: =IF(D32<>"L","-",IF(COUNTA(P!E$2:E$1000)+COUNTA(D!E$2:E$1000)+COUNTA('C'!E$2:E$1000)+COUNTA(A!E$2:E$1000)=0,C32,ROUND(C32*MAX(0.1,IFERROR(Dashboard!B$3/Dashboard!B$10,1))*(1+Dashboard!F$8*IF(B32="Occ",0.5,IF(B32="Pun",0.35,IF(B32="Tit",0.25,IF(B32="Scm",0.15,0.05))))),0))) -> 1
A33: LUCCA | B33: Sca | C33: 1 | D33: L | F33: =IF(D33<>"L","-",IF(COUNTA(P!E$2:E$1000)+COUNTA(D!E$2:E$1000)+COUNTA('C'!E$2:E$1000)+COUNTA(A!E$2:E$1000)=0,C33,ROUND(C33*MAX(0.1,IFERROR(Dashboard!B$3/Dashboard!B$10,1))*(1+Dashboard!F$8*IF(B33="Occ",0.5,IF(B33="Pun",0.35,IF(B33="Tit",0.25,IF(B33="Scm",0.15,0.05))))),0))) -> 1 | G33: con Hojlund
A34: MALDINI | B34: Sca | C34: 10 | D34: L | F34: =IF(D34<>"L","-",IF(COUNTA(P!E$2:E$1000)+COUNTA(D!E$2:E$1000)+COUNTA('C'!E$2:E$1000)+COUNTA(A!E$2:E$1000)=0,C34,ROUND(C34*MAX(0.1,IFERROR(Dashboard!B$3/Dashboard!B$10,1))*(1+Dashboard!F$8*IF(B34="Occ",0.5,IF(B34="Pun",0.35,IF(B34="Tit",0.25,IF(B34="Scm",0.15,0.05))))),0))) -> 10
A35: MALEN | B35: Pun | C35: 250 | D35: L | F35: =IF(D35<>"L","-",IF(COUNTA(P!E$2:E$1000)+COUNTA(D!E$2:E$1000)+COUNTA('C'!E$2:E$1000)+COUNTA(A!E$2:E$1000)=0,C35,ROUND(C35*MAX(0.1,IFERROR(Dashboard!B$3/Dashboard!B$10,1))*(1+Dashboard!F$8*IF(B35="Occ",0.5,IF(B35="Pun",0.35,IF(B35="Tit",0.25,IF(B35="Scm",0.15,0.05))))),0))) -> 250 | G35: Rig.
A36: MARTINEZ L. | B36: Pun | C36: 250 | D36: L | F36: =IF(D36<>"L","-",IF(COUNTA(P!E$2:E$1000)+COUNTA(D!E$2:E$1000)+COUNTA('C'!E$2:E$1000)+COUNTA(A!E$2:E$1000)=0,C36,ROUND(C36*MAX(0.1,IFERROR(Dashboard!B$3/Dashboard!B$10,1))*(1+Dashboard!F$8*IF(B36="Occ",0.5,IF(B36="Pun",0.35,IF(B36="Tit",0.25,IF(B36="Scm",0.15,0.05))))),0))) -> 250
A37: MENDY P. | B37: Scm | C37: 1 | D37: L | F37: =IF(D37<>"L","-",IF(COUNTA(P!E$2:E$1000)+COUNTA(D!E$2:E$1000)+COUNTA('C'!E$2:E$1000)+COUNTA(A!E$2:E$1000)=0,C37,ROUND(C37*MAX(0.1,IFERROR(Dashboard!B$3/Dashboard!B$10,1))*(1+Dashboard!F$8*IF(B37="Occ",0.5,IF(B37="Pun",0.35,IF(B37="Tit",0.25,IF(B37="Scm",0.15,0.05))))),0))) -> 1
A38: MOTA | B38: Pun | C38: 10 | D38: L | F38: =IF(D38<>"L","-",IF(COUNTA(P!E$2:E$1000)+COUNTA(D!E$2:E$1000)+COUNTA('C'!E$2:E$1000)+COUNTA(A!E$2:E$1000)=0,C38,ROUND(C38*MAX(0.1,IFERROR(Dashboard!B$3/Dashboard!B$10,1))*(1+Dashboard!F$8*IF(B38="Occ",0.5,IF(B38="Pun",0.35,IF(B38="Tit",0.25,IF(B38="Scm",0.15,0.05))))),0))) -> 10
A39: N'DRI | B39: Tit | C39: 1 | D39: L | F39: =IF(D39<>"L","-",IF(COUNTA(P!E$2:E$1000)+COUNTA(D!E$2:E$1000)+COUNTA('C'!E$2:E$1000)+COUNTA(A!E$2:E$1000)=0,C39,ROUND(C39*MAX(0.1,IFERROR(Dashboard!B$3/Dashboard!B$10,1))*(1+Dashboard!F$8*IF(B39="Occ",0.5,IF(B39="Pun",0.35,IF(B39="Tit",0.25,IF(B39="Scm",0.15,0.05))))),0))) -> 1
A40: NERES | B40: Sca | C40: 1 | D40: L | F40: =IF(D40<>"L","-",IF(COUNTA(P!E$2:E$1000)+COUNTA(D!E$2:E$1000)+COUNTA('C'!E$2:E$1000)+COUNTA(A!E$2:E$1000)=0,C40,ROUND(C40*MAX(0.1,IFERROR(Dashboard!B$3/Dashboard!B$10,1))*(1+Dashboard!F$8*IF(B40="Occ",0.5,IF(B40="Pun",0.35,IF(B40="Tit",0.25,IF(B40="Scm",0.15,0.05))))),0))) -> 1
...

Sheet Dashboard
A1: Budget Iniziale | B1: 500
A2: Crediti Spesi | B2: =E5+E6+E7+E8+SUM(Extra!C2:C5) -> 0 | G2: Ruolo | H2: Target O/P | I2: Target Tit | J2: Poss. O/P | K2: Poss Tit. | L2: Nec. O/P | M2: Nec. Tit | N2: Nec. Scm/Sca | O2: Futuro se O/P | P2: Futuro se Tit | Q2: Futuro se Scm/Sca | R2: Atteso Attuale | S2: Atteso dopo O/P | T2: Atteso dopo Tit | U2: Atteso dopo Scm/Sca | V2: Fattore O/P | W2: Fattore Tit | X2: Fattore Scm/Sca | Y2: Potenza | Z2: Tolleranza P | AA2: 0.9
A3: Crediti Residui | B3: =B1-B2 -> 500 | Z3: Tolleranza D | AA3: 0.9
A4: Budget Medio / Slot | B4: =IF(B9>0, B3/B9, 0) -> 20 | Z4: Tolleranza C | AA4: 0.8
A5: Slot Portieri (Tot / Liberi) | B5: 3 | C5: =B5-COUNTIF(P!D:D,"M")-Extra!B2 -> 3 | D5: 30 | E5: =SUMIF(P!D:D,"M",P!E:E)+Extra!C2 -> 0 | F5: =1 - (((COUNTIFS(P!B:B,"Occ",P!D:D,"L")*5) + (COUNTIFS(P!B:B,"Pun",P!D:D,"L")*4) + (COUNTIFS(P!B:B,"Tit",P!D:D,"L")*3) + (COUNTIFS(P!B:B,"Scm",P!D:D,"L")*2) + (COUNTIFS(P!B:B,"Sca",P!D:D,"L")*1)) / ((COUNTIF(P!B:B,"Occ")*5) + (COUNTIF(P!B:B,"Pun")*4) + (COUNTIF(P!B:B,"Tit")*3) + (COUNTIF(P!B:B,"Scm")*2) + (COUNTIF(P!B:B,"Sca")*1))) -> 0 | G5: P | H5: =ROUNDUP($B5*30%,0) -> 1 | I5: =ROUNDUP($B5*30%,0) -> 1 | J5: =COUNTIFS(P!B:B,"Occ",P!D:D,"M")+COUNTIFS(P!B:B,"Pun",P!D:D,"M") -> 0 | K5: =COUNTIFS(P!B:B,"Tit",P!D:D,"M") -> 0 | L5: =MAX(0,H5-J5) -> 1 | M5: =MAX(0,I5-K5) -> 1 | N5: =MAX(0,C5-L5-M5) -> 1 | O5: =IFERROR(($D5/$B5)*1.425/1.2425,0) -> 11.468813 | P5: =IFERROR(($D5/$B5)*1.25/1.2425,0) -> 10.060362 | Q5: =IFERROR(($D5/$B5)*1.1/1.2425,0) -> 8.8531187 | R5: =L5*O5+M5*P5+N5*Q5 -> 30.382294 | S5: =MAX(0,L5-1)*O5+M5*P5+MAX(0,C5-1-MAX(0,L5-1)-M5)*Q5 -> 18.913481 | T5: =L5*O5+MAX(0,M5-1)*P5+MAX(0,C5-1-L5-MAX(0,M5-1))*Q5 -> 20.321932 | U5: =L5*O5+M5*P5+MAX(0,C5-1-L5-M5)*Q5 -> 21.529175 | V5: =MAX(0,MIN(1,IFERROR(($D5-$E5)/(($O5+$S5)*$AA$2),1)))^$Y5 -> 1 | W5: =MAX(0,MIN(1,IFERROR(($D5-$E5)/(($P5+$T5)*$AA$2),1)))^$Y5 -> 1 | X5: =MAX(0,MIN(1,IFERROR(($D5-$E5)/(($Q5+$U5)*$AA$2),1)))^$Y5 -> 1 | Y5: 3
A6: Slot Difensori (Tot / Liberi) | B6: 8 | C6: =B6-COUNTIF(D!D:D,"M")-Extra!B3 -> 8 | D6: 45 | E6: =SUMIF(D!D:D,"M",D!E:E)+Extra!C3 -> 0 | F6: =1 - (((COUNTIFS(D!B:B,"Occ",D!D:D,"L")*5) + (COUNTIFS(D!B:B,"Pun",D!D:D,"L")*4) + (COUNTIFS(D!B:B,"Tit",D!D:D,"L")*3) + (COUNTIFS(D!B:B,"Scm",D!D:D,"L")*2) + (COUNTIFS(D!B:B,"Sca",D!D:D,"L")*1)) / ((COUNTIF(D!B:B,"Occ")*5) + (COUNTIF(D!B:B,"Pun")*4) + (COUNTIF(D!B:B,"Tit")*3) + (COUNTIF(D!B:B,"Scm")*2) + (COUNTIF(D!B:B,"Sca")*1))) -> 0 | G6: D | H6: =ROUNDUP($B6*30%,0) -> 3 | I6: =ROUNDUP($B6*20%,0) -> 2 | J6: =COUNTIFS(D!B:B,"Occ",D!D:D,"M")+COUNTIFS(D!B:B,"Pun",D!D:D,"M") -> 0 | K6: =COUNTIFS(D!B:B,"Tit",D!D:D,"M") -> 0 | L6: =MAX(0,H6-J6) -> 3 | M6: =MAX(0,I6-K6) -> 2 | N6: =MAX(0,C6-L6-M6) -> 3 | O6: =IFERROR(($D6/$B6)*1.425/1.2425,0) -> 6.4512072 | P6: =IFERROR(($D6/$B6)*1.25/1.2425,0) -> 5.6589537 | Q6: =IFERROR(($D6/$B6)*1.1/1.2425,0) -> 4.9798793 | R6: =L6*O6+M6*P6+N6*Q6 -> 45.611167 | S6: =MAX(0,L6-1)*O6+M6*P6+MAX(0,C6-1-MAX(0,L6-1)-M6)*Q6 -> 39.15996 | T6: =L6*O6+MAX(0,M6-1)*P6+MAX(0,C6-1-L6-MAX(0,M6-1))*Q6 -> 39.952213 | U6: =L6*O6+M6*P6+MAX(0,C6-1-L6-M6)*Q6 -> 40.631288 | V6: =MAX(0,MIN(1,IFERROR(($D6-$E6)/(($O6+$S6)*$AA$3),1)))^$Y6 -> 1 | W6: =MAX(0,MIN(1,IFERROR(($D6-$E6)/(($P6+$T6)*$AA$3),1)))^$Y6 -> 1 | X6: =MAX(0,MIN(1,IFERROR(($D6-$E6)/(($Q6+$U6)*$AA$3),1)))^$Y6 -> 1 | Y6: 2
A7: Slot Centrocampisti (Tot / Liberi) | B7: 8 | C7: =B7-COUNTIF('C'!D:D,"M")-Extra!B4 -> 8 | D7: 100 | E7: =SUMIF('C'!D:D,"M",'C'!E:E)+Extra!C4 -> 0 | F7: =1 - (((COUNTIFS('C'!B:B,"Occ",'C'!D:D,"L")*5) + (COUNTIFS('C'!B:B,"Pun",'C'!D:D,"L")*4) + (COUNTIFS('C'!B:B,"Tit",'C'!D:D,"L")*3) + (COUNTIFS('C'!B:B,"Scm",'C'!D:D,"L")*2) + (COUNTIFS('C'!B:B,"Sca",'C'!D:D,"L")*1)) / ((COUNTIF('C'!B:B,"Occ")*5) + (COUNTIF('C'!B:B,"Pun")*4) + (COUNTIF('C'!B:B,"Tit")*3) + (COUNTIF('C'!B:B,"Scm")*2) + (COUNTIF('C'!B:B,"Sca")*1))) -> 0 | G7: C | H7: =ROUNDUP($B7*30%,0) -> 3 | I7: =ROUNDUP($B7*20%,0) -> 2 | J7: =COUNTIFS('C'!B:B,"Occ",'C'!D:D,"M")+COUNTIFS('C'!B:B,"Pun",'C'!D:D,"M") -> 0 | K7: =COUNTIFS('C'!B:B,"Tit",'C'!D:D,"M") -> 0 | L7: =MAX(0,H7-J7) -> 3 | M7: =MAX(0,I7-K7) -> 2 | N7: =MAX(0,C7-L7-M7) -> 3 | O7: =IFERROR(($D7/$B7)*1.425/1.2425,0) -> 14.336016 | P7: =IFERROR(($D7/$B7)*1.25/1.2425,0) -> 12.575453 | Q7: =IFERROR(($D7/$B7)*1.1/1.2425,0) -> 11.066398 | R7: =L7*O7+M7*P7+N7*Q7 -> 101.35815 | S7: =MAX(0,L7-1)*O7+M7*P7+MAX(0,C7-1-MAX(0,L7-1)-M7)*Q7 -> 87.022133 | T7: =L7*O7+MAX(0,M7-1)*P7+MAX(0,C7-1-L7-MAX(0,M7-1))*Q7 -> 88.782696 | U7: =L7*O7+M7*P7+MAX(0,C7-1-L7-M7)*Q7 -> 90.291751 | V7: =MAX(0,MIN(1,IFERROR(($D7-$E7)/(($O7+$S7)*$AA$4),1)))^$Y7 -> 1 | W7: =MAX(0,MIN(1,IFERROR(($D7-$E7)/(($P7+$T7)*$AA$4),1)))^$Y7 -> 1 | X7: =MAX(0,MIN(1,IFERROR(($D7-$E7)/(($Q7+$U7)*$AA$4),1)))^$Y7 -> 1 | Y7: 0.5
A8: Slot Attaccanti (Tot / Liberi) | B8: 6 | C8: =B8-COUNTIF(A!D:D,"M")-Extra!B5 -> 6 | D8: 325 | E8: =SUMIF(A!D:D,"M",A!E:E)+Extra!C5 -> 0 | F8: =1 - (((COUNTIFS(A!B:B,"Occ",A!D:D,"L")*5) + (COUNTIFS(A!B:B,"Pun",A!D:D,"L")*4) + (COUNTIFS(A!B:B,"Tit",A!D:D,"L")*3) + (COUNTIFS(A!B:B,"Scm",A!D:D,"L")*2) + (COUNTIFS(A!B:B,"Sca",A!D:D,"L")*1)) / ((COUNTIF(A!B:B,"Occ")*5) + (COUNTIF(A!B:B,"Pun")*4) + (COUNTIF(A!B:B,"Tit")*3) + (COUNTIF(A!B:B,"Scm")*2) + (COUNTIF(A!B:B,"Sca")*1))) -> 0 | G8: A | H8: =ROUNDUP($B8*30%,0) -> 2 | I8: =ROUNDUP($B8*10%,0) -> 1 | J8: =COUNTIFS(A!B:B,"Occ",A!D:D,"M")+COUNTIFS(A!B:B,"Pun",A!D:D,"M") -> 0 | K8: =COUNTIFS(A!B:B,"Tit",A!D:D,"M") -> 0 | L8: =MAX(0,H8-J8) -> 2 | M8: =MAX(0,I8-K8) -> 1 | N8: =MAX(0,C8-L8-M8) -> 3 | O8: =IFERROR(($D8/$B8)*1.425/1.2425,0) -> 62.122736 | P8: =IFERROR(($D8/$B8)*1.25/1.2425,0) -> 54.493628 | Q8: =IFERROR(($D8/$B8)*1.1/1.2425,0) -> 47.954393 | R8: =L8*O8+M8*P8+N8*Q8 -> 322.60228 | S8: =MAX(0,L8-1)*O8+M8*P8+MAX(0,C8-1-MAX(0,L8-1)-M8)*Q8 -> 260.47954 | T8: =L8*O8+MAX(0,M8-1)*P8+MAX(0,C8-1-L8-MAX(0,M8-1))*Q8 -> 268.10865 | U8: =L8*O8+M8*P8+MAX(0,C8-1-L8-M8)*Q8 -> 274.64789 | V8: 1 | W8: 1 | X8: 1 | Y8: 0
A9: Slot Liberi Totali | B9: =SUM(C5:C8) -> 25
